Workbook

Sheet MAESTRA STUDENTEN
A1: BEHEER VAN STUDENTEN
A2: Wijzig studenten hier. De dagelijkse bladen worden AUTOMATISCH bijgewerkt via formules. Studenten met status 'Verwijderd' worden niet getoond.
A4: Klas | B4: Student | C4: Status
A5: 1 Aarde | B5: Conner Wouters | C5: Actief
A6: 1 Aarde | B6: Dylan Abs | C6: Actief
A7: 1 Aarde | B7: Jaden Gesquiere | C7: Actief
A8: 1 Aarde | B8: Kaitlyn Van den Eede | C8: Actief
A9: 1 Aarde | B9: Kayden Van den Eede | C9: Actief
A10: 1 Aarde | B10: Leandro Degrendele | C10: Actief
A11: 1 Aarde | B11: Nasser Ayari | C11: Actief
A12: 1 Aarde | B12: Timothy Baert | C12: Actief
A13: 1 Aarde | B13: Virgilles Vandenbussche | C13: Actief
A14: 1 Lucht | B14: Alexander Desaever | C14: Actief
A15: 1 Lucht | B15: Emmelien Verstraete | C15: Actief
... A115: 6 Food | B115: Maylin Jonckheere | C115: Actief
A118: NIEUWE STUDENTEN (Hier toevoegen)
A119: Klas | B119: Student | C119: Status
C120: Actief
C121: Actief
C122: Actief
C123: Actief
C124: Actief
C125: Actief
C126: Actief
C127: Actief
C128: Actief
C129: Actief
C130: Actief
C131: Actief
... C139: Actief

Sheet 01-09 Ma
A1: TOTAAL PER LESUUR
B2: 1 | C2: 2 | D2: 3 | E2: 4 | F2: 5 | G2: 6 | H2: 7
A3: Chill-outs | B3: =(COUNTIF(B8:B16,"=1")*1+COUNTIF(B8:B16,"1+VR")*1+COUNTIF(B8:B16,"1+VL")*1+COUNTIF(B8:B16,"1+VR+VL")*1+COUNTIF(B8:B16,"VR+1")*1+COUNTIF(B8:B16,"VL+1")*1+COUNTIF(B8:B16,"=2")*2+COUNTIF(B8:B16,"2+VR")*2+COUNTIF(B8:B16,"2+VL")*2+COUNTIF(B8:B16,"VR+2")*2+COUNTIF(B8:B16,"VL+2")*2+COUNTIF(B8:B16,"=3")*3+COUNTIF(B8:B16,"3+VR")*3+COUNTIF(B8:B16,"3+VL")*3+COUNTIF(B8:B16,"VR+3")*3+COUNTIF(B8:B16,"VL+3")*3)+(COUNTIF(B21:B25,"=1")*1+COUNTIF(B21:B25,"1+VR")*1+COUNTIF(B21:B25,"1+VL")*1+COUNTIF(B21:B25,"1+VR+VL")*1+COUNTIF(B21:B25,"VR+1")*1+COUNTIF(B21:B25,"VL+1")*1+COUNTIF(B21:B25,"=2")*2+COUNTIF(B21:B25,"2+VR")*2+COUNTIF(B21:B25,"2+VL")*2+COUNTIF(B21:B25,"VR+2")*2+COUNTIF(B21:B25,"VL+2")*2+COUNTIF(B21:B25,"=3")*3+COUNTIF(B21:B25,"3+VR")*3+COUNTIF(B21:B25,"3+VL")*3+COUNTIF(B21:B25,"VR+3")*3+COUNTIF(B21:B25,"VL+3")*3)+(COUNTIF(B30:B37,"=1")*1+COUNTIF(B30:B37,"1+VR")*1+COUNTIF(B30:B37,"1+VL")*1+COUNTIF(B30:B37,"1+VR+VL")*1+COUNTIF(B30:B37,"VR+1")*1+COUNTIF(B30:B37,"VL+1")*1+COUNTIF(B30:B37,"=2")*2+COUNTIF(B30:B37,"2+VR")*2+COUNTIF(B30:B37,"2+VL")*2+COUNTIF(B30:B37,"VR+2")*2+COUNTIF(B30:B37,"VL+2")*2+COUNTIF(B30:B37,"=3")*3+COUNTIF(B30:B37,"3+VR")*3+COUNTIF(B30:B37,"3+VL")*3+COUNTIF(B30:B37,"VR+3")*3+COUNTIF(B30:B37,"VL+3")*3)+(COUNTIF(B42:B50,"=1")*1+COUNTIF(B42:B50,"1+VR")*1+COUNTIF(B42:B50,"1+VL")*1+COUNTIF(B42:B50,"1+VR+VL")*1+COUNTIF(B42:B50,"VR+1")*1+COUNTIF(B42:B50,"VL+1")*1+COUNTIF(B42:B50,"=2")*2+COUNTIF(B42:B50,"2+VR")*2+COUNTIF(B42:B50,"2+VL")*2+COUNTIF(B42:B50,"VR+2")*2+COUNTIF(B42:B50,"VL+2")*2+COUNTIF(B42:B50,"=3")*3+COUNTIF(B42:B50,"3+VR")*3+COUNTIF(B42:B50,"3+VL")*3+COUNTIF(B42:B50,"VR+3")*3+COUNTIF(B42:B50,"VL+3")*3)+(COUNTIF(B55:B63,"=1")*1+COUNTIF(B55:B63,"1+VR")*1+COUNTIF(B55:B63,"1+VL")*1+COUNTIF(B55:B63,"1+VR+VL")*1+COUNTIF(B55:B63,"VR+1")*1+COUNTIF(B55:B63,"VL+1")*1+COUNTIF(B55:B63,"=2")*2+COUNTIF(B55:B63,"2+VR")*2+COUNTIF(B55:B63,"2+VL")*2+COUNTIF(B55:B63,"VR+2")*2+COUNTIF(B55:B63,"VL+2")*2+COUNTIF(B55:B63,"=3")*3+COUNTIF(B55:B63,"3+VR")*3+COUNTIF(B55:B63,"3+VL")*3+COUNTIF(B55:B63,"VR+3")*3+COUNTIF(B55:B63,"VL+3")*3)+(COUNTIF(B68:B75,"=1")*1+COUNTIF(B68:B75,"1+VR")*1+COUNTIF(B68:B75,"1+VL")*1+COUNTIF(B68:B75,"1+VR+VL")*1+COUNTIF(B68:B75,"VR+1")*1+COUNTIF(B68:B75,"VL+1")*1+COUNTIF(B68:B75,"=2")*2+COUNTIF(B68:B75,"2+VR")*2+COUNTIF(B68:B75,"2+VL")*2+COUNTIF(B68:B75,"VR+2")*2+COUNTIF(B68:B75,"VL+2")*2+COUNTIF(B68:B75,"=3")*3+COUNTIF(B68:B75,"3+VR")*3+COUNTIF(B68:B75,"3+VL")*3+COUNTIF(B68:B75,"VR+3")*3+COUNTIF(B68:B75,"VL+3")*3)+(COUNTIF(B80:B83,"=1")*1+COUNTIF(B80:B83,"1+VR")*1+COUNTIF(B80:B83,"1+VL")*1+COUNTIF(B80:B83,"1+VR+VL")*1+COUNTIF(B80:B83,"VR+1")*1+COUNTIF(B80:B83,"VL+1")*1+COUNTIF(B80:B83,"=2")*2+COUNTIF(B80:B83,"2+VR")*2+COUNTIF(B80:B83,"2+VL")*2+COUNTIF(B80:B83,"VR+2")*2+COUNTIF(B80:B83,"VL+2")*2+COUNTIF(B80:B83,"=3")*3+COUNTIF(B80:B83,"3+VR")*3+COUNTIF(B80:B83,"3+VL")*3+COUNTIF(B80:B83,"VR+3")*3+COUNTIF(B80:B83,"VL+3")*3)+(COUNTIF(B88:B91,"=1")*1+COUNTIF(B88:B91,"1+VR")*1+COUNTIF(B88:B91,"1+VL")*1+COUNTIF(B88:B91,"1+VR+VL")*1+COUNTIF(B88:B91,"VR+1")*1+COUNTIF(B88:B91,"VL+1")*1+COUNTIF(B88:B91,"=2")*2+COUNTIF(B88:B91,"2+VR")*2+COUNTIF(B88:B91,"2+VL")*2+COUNTIF(B88:B91,"VR+2")*2+COUNTIF(B88:B91,"VL+2")*2+COUNTIF(B88:B91,"=3")*3+COUNTIF(B88:B91,"3+VR")*3+COUNTIF(B88:B91,"3+VL")*3+COUNTIF(B88:B91,"VR+3")*3+COUNTIF(B88:B91,"VL+3")*3)+(COUNTIF(B96:B105,"=1")*1+COUNTIF(B96:B105,"1+VR")*1+COUNTIF(B96:B105,"1+VL")*1+COUNTIF(B96:B105,"1+VR+VL")*1+COUNTIF(B96:B105,"VR+1")*1+COUNTIF(B96:B105,"VL+1")*1+COUNTIF(B96:B105,"=2")*2+COUNTIF(B96:B105,"2+VR")*2+COUNTIF(B96:B105,"2+VL")*2+COUNTIF(B96:B105,"VR+2")*2+COUNTIF(B96:B105,"VL+2")*2+COUNTIF(B96:B105,"=3")*3+COUNTIF(B96:B105,"3+VR")*3+COUNTIF(B96:B105,"3+VL")*3+COUNTIF(B96:B105,"VR+3")*3+COUNTIF(B96:B105,"VL+3")*3)+(COUNTIF(B110:B115,"=1")*1+COUNTIF(B110:B115,"1+VR")*1+COUNTIF(B110:B115,"1+VL")*1+COUNTIF(B110:B115,"1+VR+VL")*1+COUNTIF(B110:B115,"VR+1")*1+COUNTIF(B110:B115,"VL+1")*1+COUNTIF(B110:B115,"=2")*2+COUNTIF(B110:B115,"2+VR")*2+COUNTIF(B110:B115,"2+VL")*2+COUNTIF(B110:B115,"VR+2")*2+COUNTIF(B110:B115,"VL+2")*2+COUNTIF(B110:B115,"=3")*3+COUNTIF(B110:B115,"3+VR")*3+COUNTIF(B110:B115,"3+VL")*3+COUNTIF(B110:B115,"VR+3")*3+COUNTIF(B110:B115,"VL+3")*3)+(COUNTIF(B120:B125,"=1")*1+COUNTIF(B120:B125,"1+VR")*1+COUNTIF(B120:B125,"1+VL")*1+COUNTIF(B120:B125,"1+VR+VL")*1+COUNTIF(B120:B125,"VR+1")*1+COUNTIF(B120:B125,"VL+1")*1+COUNTIF(B120:B125,"=2")*2+COUNTIF(B120:B125,"2+VR")*2+COUNTIF(B120:B125,"2+VL")*2+COUNTIF(B120:B125,"VR+2")*2+COUNTIF(B120:B125,"VL+2")*2+COUNTIF(B120:B125,"=3")*3+COUNTIF(B120:B125,"3+VR")*3+COUNTIF(B120:B125,"3+VL")*3+COUNTIF(B120:B125,"VR+3")*3+COUNTIF(B120:B125,"VL+3")*3)+(COUNTIF(B130:B131,"=1")*1+COUNTIF(B130:B131,"1+VR")*1+COUNTIF(B130:B131,"1+VL")*1+COUNTIF(B130:B131,"1+VR+VL")*1+COUNTIF(B130:B131,"VR+1")*1+COUNTIF(B130:B131,"VL+1")*1+COUNTIF(B130:B131,"=2")*2+COUNTIF(B130:B131,"2+VR")*2+COUNTIF(B130:B131,"2+VL")*2+COUNTIF(B130:B131,"VR+2")*2+COUNTIF(B130:B131,"VL+2")*2+COUNTIF(B130:B131,"=3")*3+COUNTIF(B130:B131,"3+VR")*3+COUNTIF(B130:B131,"3+VL")*3+COUNTIF(B130:B131,"VR+3")*3+COUNTIF(B130:B131,"VL+3")*3)+(COUNTIF(B136:B137,"=1")*1+COUNTIF(B136:B137,"1+VR")*1+COUNTIF(B136:B137,"1+VL")*1+COUNTIF(B136:B137,"1+VR+VL")*1+COUNTIF(B136:B137,"VR+1")*1+COUNTIF(B136:B137,"VL+1")*1+COUNTIF(B136:B137,"=2")*2+COUNTIF(B136:B137,"2+VR")*2+COUNTIF(B136:B137,"2+VL")*2+COUNTIF(B136:B137,"VR+2")*2+COUNTIF(B136:B137,"VL+2")*2+COUNTIF(B136:B137,"=3")*3+COUNTIF(B136:B137,"3+VR")*3+COUNTIF(B136:B137,"3+VL")*3+COUNTIF(B136:B137,"VR+3")*3+COUNTIF(B136:B137,"VL+3")*3)+(COUNTIF(B142:B147,"=1")*1+COUNTIF(B142:B147,"1+VR")*1+COUNTIF(B142:B147,"1+VL")*1+COUNTIF(B142:B147,"1+VR+VL")*1+COUNTIF(B142:B147,"VR+1")*1+COUNTIF(B142:B147,"VL+1")*1+COUNTIF(B142:B147,"=2")*2+COUNTIF(B142:B147,"2+VR")*2+COUNTIF(B142:B147,"2+VL")*2+COUNTIF(B142:B147,"VR+2")*2+COUNTIF(B142:B147,"VL+2")*2+COUNTIF(B142:B147,"=3")*3+COUNTIF(B142:B147,"3+VR")*3+COUNTIF(B142:B147,"3+VL")*3+COUNTIF(B142:B147,"VR+3")*3+COUNTIF(B142:B147,"VL+3")*3)+(COUNTIF(B152:B156,"=1")*1+COUNTIF(B152:B156,"1+VR")*1+COUNTIF(B152:B156,"1+VL")*1+COUNTIF(B152:B156,"1+VR+VL")*1+COUNTIF(B152:B156,"VR+1")*1+COUNTIF(B152:B156,"VL+1")*1+COUNTIF(B152:B156,"=2")*2+COUNTIF(B152:B156,"2+VR")*2+COUNTIF(B152:B156,"2+VL")*2+COUNTIF(B152:B156,"VR+2")*2+COUNTIF(B152:B156,"VL+2")*2+COUNTIF(B152:B156,"=3")*3+COUNTIF(B152:B156,"3+VR")*3+COUNTIF(B152:B156,"3+VL")*3+COUNTIF(B152:B156,"VR+3")*3+COUNTIF(B152:B156,"VL+3")*3)+(COUNTIF(B161:B163,"=1")*1+COUNTIF(B161:B163,"1+VR")*1+COUNTIF(B161:B163,"1+VL")*1+COUNTIF(B161:B163,"1+VR+VL")*1+COUNTIF(B161:B163,"VR+1")*1+COUNTIF(B161:B163,"VL+1")*1+COUNTIF(B161:B163,"=2")*2+COUNTIF(B161:B163,"2+VR")*2+COUNTIF(B161:B163,"2+VL")*2+COUNTIF(B161:B163,"VR+2")*2+COUNTIF(B161:B163,"VL+2")*2+COUNTIF(B161:B163,"=3")*3+COUNTIF(B161:B163,"3+VR")*3+COUNTIF(B161:B163,"3+VL")*3+COUNTIF(B161:B163,"VR+3")*3+COUNTIF(B161:B163,"VL+3")*3)+(COUNTIF(B168:B168,"=1")*1+COUNTIF(B168:B168,"1+VR")*1+COUNTIF(B168:B168,"1+VL")*1+COUNTIF(B168:B168,"1+VR+VL")*1+COUNTIF(B168:B168,"VR+1")*1+COUNTIF(B168:B168,"VL+1")*1+COUNTIF(B168:B168,"=2")*2+COUNTIF(B168:B168,"2+VR")*2+COUNTIF(B168:B168,"2+VL")*2+COUNTIF(B168:B168,"VR+2")*2+COUNTIF(B168:B168,"VL+2")*2+COUNTIF(B168:B168,"=3")*3+COUNTIF(B168:B168,"3+VR")*3+COUNTIF(B168:B168,"3+VL")*3+COUNTIF(B168:B168,"VR+3")*3+COUNTIF(B168:B168,"VL+3")*3)+(COUNTIF(K8:K14,"=1")*1+COUNTIF(K8:K14,"1+VR")*1+COUNTIF(K8:K14,"1+VL")*1+COUNTIF(K8:K14,"1+VR+VL")*1+COUNTIF(K8:K14,"VR+1")*1+COUNTIF(K8:K14,"VL+1")*1+COUNTIF(K8:K14,"=2")*2+COUNTIF(K8:K14,"2+VR")*2+COUNTIF(K8:K14,"2+VL")*2+COUNTIF(K8:K14,"VR+2")*2+COUNTIF(K8:K14,"VL+2")*2+COUNTIF(K8:K14,"=3")*3+COUNTIF(K8:K14,"3+VR")*3+COUNTIF(K8:K14,"3+VL")*3+COUNTIF(K8:K14,"VR+3")*3+COUNTIF(K8:K14,"VL+3")*3)+(COUNTIF(K19:K25,"=1")*1+COUNTIF(K19:K25,"1+VR")*1+COUNTIF(K19:K25,"1+VL")*1+COUNTIF(K19:K25,"1+VR+VL")*1+COUNTIF(K19:K25,"VR+1")*1+COUNTIF(K19:K25,"VL+1")*1+COUNTIF(K19:K25,"=2")*2+COUNTIF(K19:K25,"2+VR")*2+COUNTIF(K19:K25,"2+VL")*2+COUNTIF(K19:K25,"VR+2")*2+COUNTIF(K19:K25,"VL+2")*2+COUNTIF(K19:K25,"=3")*3+COUNTIF(K19:K25,"3+VR")*3+COUNTIF(K19:K25,"3+VL")*3+COUNTIF(K19:K25,"VR+3")*3+COUNTIF(K19:K25,"VL+3")*3) | C3: =(COUNTIF(C8:C16,"=1")*1+COUNTIF(C8:C16,"1+VR")*1+COUNTIF(C8:C16,"1+VL")*1+COUNTIF(C8:C16,"1+VR+VL")*1+COUNTIF(C8:C16,"VR+1")*1+COUNTIF(C8:C16,"VL+1")*1+COUNTIF(C8:C16,"=2")*2+COUNTIF(C8:C16,"2+VR")*2+COUNTIF(C8:C16,"2+VL")*2+COUNTIF(C8:C16,"VR+2")*2+COUNTIF(C8:C16,"VL+2")*2+COUNTIF(C8:C16,"=3")*3+COUNTIF(C8:C16,"3+VR")*3+COUNTIF(C8:C16,"3+VL")*3+COUNTIF(C8:C16,"VR+3")*3+COUNTIF(C8:C16,"VL+3")*3)+(COUNTIF(C21:C25,"=1")*1+COUNTIF(C21:C25,"1+VR")*1+COUNTIF(C21:C25,"1+VL")*1+COUNTIF(C21:C25,"1+VR+VL")*1+COUNTIF(C21:C25,"VR+1")*1+COUNTIF(C21:C25,"VL+1")*1+COUNTIF(C21:C25,"=2")*2+COUNTIF(C21:C25,"2+VR")*2+COUNTIF(C21:C25,"2+VL")*2+COUNTIF(C21:C25,"VR+2")*2+COUNTIF(C21:C25,"VL+2")*2+COUNTIF(C21:C25,"=3")*3+COUNTIF(C21:C25,"3+VR")*3+COUNTIF(C21:C25,"3+VL")*3+COUNTIF(C21:C25,"VR+3")*3+COUNTIF(C21:C25,"VL+3")*3)+(COUNTIF(C30:C37,"=1")*1+COUNTIF(C30:C37,"1+VR")*1+COUNTIF(C30:C37,"1+VL")*1+COUNTIF(C30:C37,"1+VR+VL")*1+COUNTIF(C30:C37,"VR+1")*1+COUNTIF(C30:C37,"VL+1")*1+COUNTIF(C30:C37,"=2")*2+COUNTIF(C30:C37,"2+VR")*2+COUNTIF(C30:C37,"2+VL")*2+COUNTIF(C30:C37,"VR+2")*2+COUNTIF(C30:C37,"VL+2")*2+COUNTIF(C30:C37,"=3")*3+COUNTIF(C30:C37,"3+VR")*3+COUNTIF(C30:C37,"3+VL")*3+COUNTIF(C30:C37,"VR+3")*3+COUNTIF(C30:C37,"VL+3")*3)+(COUNTIF(C42:C50,"=1")*1+COUNTIF(C42:C50,"1+VR")*1+COUNTIF(C42:C50,"1+VL")*1+COUNTIF(C42:C50,"1+VR+VL")*1+COUNTIF(C42:C50,"VR+1")*1+COUNTIF(C42:C50,"VL+1")*1+COUNTIF(C42:C50,"=2")*2+COUNTIF(C42:C50,"2+VR")*2+COUNTIF(C42:C50,"2+VL")*2+COUNTIF(C42:C50,"VR+2")*2+COUNTIF(C42:C50,"VL+2")*2+COUNTIF(C42:C50,"=3")*3+COUNTIF(C42:C50,"3+VR")*3+COUNTIF(C42:C50,"3+VL")*3+COUNTIF(C42:C50,"VR+3")*3+COUNTIF(C42:C50,"VL+3")*3)+(COUNTIF(C55:C63,"=1")*1+COUNTIF(C55:C63,"1+VR")*1+COUNTIF(C55:C63,"1+VL")*1+COUNTIF(C55:C63,"1+VR+VL")*1+COUNTIF(C55:C63,"VR+1")*1+COUNTIF(C55:C63,"VL+1")*1+COUNTIF(C55:C63,"=2")*2+COUNTIF(C55:C63,"2+VR")*2+COUNTIF(C55:C63,"2+VL")*2+COUNTIF(C55:C63,"VR+2")*2+COUNTIF(C55:C63,"VL+2")*2+COUNTIF(C55:C63,"=3")*3+COUNTIF(C55:C63,"3+VR")*3+COUNTIF(C55:C63,"3+VL")*3+COUNTIF(C55:C63,"VR+3")*3+COUNTIF(C55:C63,"VL+3")*3)+(COUNTIF(C68:C75,"=1")*1+COUNTIF(C68:C75,"1+VR")*1+COUNTIF(C68:C75,"1+VL")*1+COUNTIF(C68:C75,"1+VR+VL")*1+COUNTIF(C68:C75,"VR+1")*1+COUNTIF(C68:C75,"VL+1")*1+COUNTIF(C68:C75,"=2")*2+COUNTIF(C68:C75,"2+VR")*2+COUNTIF(C68:C75,"2+VL")*2+COUNTIF(C68:C75,"VR+2")*2+COUNTIF(C68:C75,"VL+2")*2+COUNTIF(C68:C75,"=3")*3+COUNTIF(C68:C75,"3+VR")*3+COUNTIF(C68:C75,"3+VL")*3+COUNTIF(C68:C75,"VR+3")*3+COUNTIF(C68:C75,"VL+3")*3)+(COUNTIF(C80:C83,"=1")*1+COUNTIF(C80:C83,"1+VR")*1+COUNTIF(C80:C83,"1+VL")*1+COUNTIF(C80:C83,"1+VR+VL")*1+COUNTIF(C80:C83,"VR+1")*1+COUNTIF(C80:C83,"VL+1")*1+COUNTIF(C80:C83,"=2")*2+COUNTIF(C80:C83,"2+VR")*2+COUNTIF(C80:C83,"2+VL")*2+COUNTIF(C80:C83,"VR+2")*2+COUNTIF(C80:C83,"VL+2")*2+COUNTIF(C80:C83,"=3")*3+COUNTIF(C80:C83,"3+VR")*3+COUNTIF(C80:C83,"3+VL")*3+COUNTIF(C80:C83,"VR+3")*3+COUNTIF(C80:C83,"VL+3")*3)+(COUNTIF(C88:C91,"=1")*1+COUNTIF(C88:C91,"1+VR")*1+COUNTIF(C88:C91,"1+VL")*1+COUNTIF(C88:C91,"1+VR+VL")*1+COUNTIF(C88:C91,"VR+1")*1+COUNTIF(C88:C91,"VL+1")*1+COUNTIF(C88:C91,"=2")*2+COUNTIF(C88:C91,"2+VR")*2+COUNTIF(C88:C91,"2+VL")*2+COUNTIF(C88:C91,"VR+2")*2+COUNTIF(C88:C91,"VL+2")*2+COUNTIF(C88:C91,"=3")*3+COUNTIF(C88:C91,"3+VR")*3+COUNTIF(C88:C91,"3+VL")*3+COUNTIF(C88:C91,"VR+3")*3+COUNTIF(C88:C91,"VL+3")*3)+(COUNTIF(C96:C105,"=1")*1+COUNTIF(C96:C105,"1+VR")*1+COUNTIF(C96:C105,"1+VL")*1+COUNTIF(C96:C105,"1+VR+VL")*1+COUNTIF(C96:C105,"VR+1")*1+COUNTIF(C96:C105,"VL+1")*1+COUNTIF(C96:C105,"=2")*2+COUNTIF(C96:C105,"2+VR")*2+COUNTIF(C96:C105,"2+VL")*2+COUNTIF(C96:C105,"VR+2")*2+COUNTIF(C96:C105,"VL+2")*2+COUNTIF(C96:C105,"=3")*3+COUNTIF(C96:C105,"3+VR")*3+COUNTIF(C96:C105,"3+VL")*3+COUNTIF(C96:C105,"VR+3")*3+COUNTIF(C96:C105,"VL+3")*3)+(COUNTIF(C110:C115,"=1")*1+COUNTIF(C110:C115,"1+VR")*1+COUNTIF(C110:C115,"1+VL")*1+COUNTIF(C110:C115,"1+VR+VL")*1+COUNTIF(C110:C115,"VR+1")*1+COUNTIF(C110:C115,"VL+1")*1+COUNTIF(C110:C115,"=2")*2+COUNTIF(C110:C115,"2+VR")*2+COUNTIF(C110:C115,"2+VL")*2+COUNTIF(C110:C115,"VR+2")*2+COUNTIF(C110:C115,"VL+2")*2+COUNTIF(C110:C115,"=3")*3+COUNTIF(C110:C115,"3+VR")*3+COUNTIF(C110:C115,"3+VL")*3+COUNTIF(C110:C115,"VR+3")*3+COUNTIF(C110:C115,"VL+3")*3)+(COUNTIF(C120:C125,"=1")*1+COUNTIF(C120:C125,"1+VR")*1+COUNTIF(C120:C125,"1+VL")*1+COUNTIF(C120:C125,"1+VR+VL")*1+COUNTIF(C120:C125,"VR+1")*1+COUNTIF(C120:C125,"VL+1")*1+COUNTIF(C120:C125,"=2")*2+COUNTIF(C120:C125,"2+VR")*2+COUNTIF(C120:C125,"2+VL")*2+COUNTIF(C120:C125,"VR+2")*2+COUNTIF(C120:C125,"VL+2")*2+COUNTIF(C120:C125,"=3")*3+COUNTIF(C120:C125,"3+VR")*3+COUNTIF(C120:C125,"3+VL")*3+COUNTIF(C120:C125,"VR+3")*3+COUNTIF(C120:C125,"VL+3")*3)+(COUNTIF(C130:C131,"=1")*1+COUNTIF(C130:C131,"1+VR")*1+COUNTIF(C130:C131,"1+VL")*1+COUNTIF(C130:C131,"1+VR+VL")*1+COUNTIF(C130:C131,"VR+1")*1+COUNTIF(C130:C131,"VL+1")*1+COUNTIF(C130:C131,"=2")*2+COUNTIF(C130:C131,"2+VR")*2+COUNTIF(C130:C131,"2+VL")*2+COUNTIF(C130:C131,"VR+2")*2+COUNTIF(C130:C131,"VL+2")*2+COUNTIF(C130:C131,"=3")*3+COUNTIF(C130:C131,"3+VR")*3+COUNTIF(C130:C131,"3+VL")*3+COUNTIF(C130:C131,"VR+3")*3+COUNTIF(C130:C131,"VL+3")*3)+(COUNTIF(C136:C137,"=1")*1+COUNTIF(C136:C137,"1+VR")*1+COUNTIF(C136:C137,"1+VL")*1+COUNTIF(C136:C137,"1+VR+VL")*1+COUNTIF(C136:C137,"VR+1")*1+COUNTIF(C136:C137,"VL+1")*1+COUNTIF(C136:C137,"=2")*2+COUNTIF(C136:C137,"2+VR")*2+COUNTIF(C136:C137,"2+VL")*2+COUNTIF(C136:C137,"VR+2")*2+COUNTIF(C136:C137,"VL+2")*2+COUNTIF(C136:C137,"=3")*3+COUNTIF(C136:C137,"3+VR")*3+COUNTIF(C136:C137,"3+VL")*3+COUNTIF(C136:C137,"VR+3")*3+COUNTIF(C136:C137,"VL+3")*3)+(COUNTIF(C142:C147,"=1")*1+COUNTIF(C142:C147,"1+VR")*1+COUNTIF(C142:C147,"1+VL")*1+COUNTIF(C142:C147,"1+VR+VL")*1+COUNTIF(C142:C147,"VR+1")*1+COUNTIF(C142:C147,"VL+1")*1+COUNTIF(C142:C147,"=2")*2+COUNTIF(C142:C147,"2+VR")*2+COUNTIF(C142:C147,"2+VL")*2+COUNTIF(C142:C147,"VR+2")*2+COUNTIF(C142:C147,"VL+2")*2+COUNTIF(C142:C147,"=3")*3+COUNTIF(C142:C147,"3+VR")*3+COUNTIF(C142:C147,"3+VL")*3+COUNTIF(C142:C147,"VR+3")*3+COUNTIF(C142:C147,"VL+3")*3)+(COUNTIF(C152:C156,"=1")*1+COUNTIF(C152:C156,"1+VR")*1+COUNTIF(C152:C156,"1+VL")*1+COUNTIF(C152:C156,"1+VR+VL")*1+COUNTIF(C152:C156,"VR+1")*1+COUNTIF(C152:C156,"VL+1")*1+COUNTIF(C152:C156,"=2")*2+COUNTIF(C152:C156,"2+VR")*2+COUNTIF(C152:C156,"2+VL")*2+COUNTIF(C152:C156,"VR+2")*2+COUNTIF(C152:C156,"VL+2")*2+COUNTIF(C152:C156,"=3")*3+COUNTIF(C152:C156,"3+VR")*3+COUNTIF(C152:C156,"3+VL")*3+COUNTIF(C152:C156,"VR+3")*3+COUNTIF(C152:C156,"VL+3")*3)+(COUNTIF(C161:C163,"=1")*1+COUNTIF(C161:C163,"1+VR")*1+COUNTIF(C161:C163,"1+VL")*1+COUNTIF(C161:C163,"1+VR+VL")*1+COUNTIF(C161:C163,"VR+1")*1+COUNTIF(C161:C163,"VL+1")*1+COUNTIF(C161:C163,"=2")*2+COUNTIF(C161:C163,"2+VR")*2+COUNTIF(C161:C163,"2+VL")*2+COUNTIF(C161:C163,"VR+2")*2+COUNTIF(C161:C163,"VL+2")*2+COUNTIF(C161:C163,"=3")*3+COUNTIF(C161:C163,"3+VR")*3+COUNTIF(C161:C163,"3+VL")*3+COUNTIF(C161:C163,"VR+3")*3+COUNTIF(C161:C163,"VL+3")*3)+(COUNTIF(C168:C168,"=1")*1+COUNTIF(C168:C168,"1+VR")*1+COUNTIF(C168:C168,"1+VL")*1+COUNTIF(C168:C168,"1+VR+VL")*1+COUNTIF(C168:C168,"VR+1")*1+COUNTIF(C168:C168,"VL+1")*1+COUNTIF(C168:C168,"=2")*2+COUNTIF(C168:C168,"2+VR")*2+COUNTIF(C168:C168,"2+VL")*2+COUNTIF(C168:C168,"VR+2")*2+COUNTIF(C168:C168,"VL+2")*2+COUNTIF(C168:C168,"=3")*3+COUNTIF(C168:C168,"3+VR")*3+COUNTIF(C168:C168,"3+VL")*3+COUNTIF(C168:C168,"VR+3")*3+COUNTIF(C168:C168,"VL+3")*3)+(COUNTIF(L8:L14,"=1")*1+COUNTIF(L8:L14,"1+VR")*1+COUNTIF(L8:L14,"1+VL")*1+COUNTIF(L8:L14,"1+VR+VL")*1+COUNTIF(L8:L14,"VR+1")*1+COUNTIF(L8:L14,"VL+1")*1+COUNTIF(L8:L14,"=2")*2+COUNTIF(L8:L14,"2+VR")*2+COUNTIF(L8:L14,"2+VL")*2+COUNTIF(L8:L14,"VR+2")*2+COUNTIF(L8:L14,"VL+2")*2+COUNTIF(L8:L14,"=3")*3+COUNTIF(L8:L14,"3+VR")*3+COUNTIF(L8:L14,"3+VL")*3+COUNTIF(L8:L14,"VR+3")*3+COUNTIF(L8:L14,"VL+3")*3)+(COUNTIF(L19:L25,"=1")*1+COUNTIF(L19:L25,"1+VR")*1+COUNTIF(L19:L25,"1+VL")*1+COUNTIF(L19:L25,"1+VR+VL")*1+COUNTIF(L19:L25,"VR+1")*1+COUNTIF(L19:L25,"VL+1")*1+COUNTIF(L19:L25,"=2")*2+COUNTIF(L19:L25,"2+VR")*2+COUNTIF(L19:L25,"2+VL")*2+COUNTIF(L19:L25,"VR+2")*2+COUNTIF(L19:L25,"VL+2")*2+COUNTIF(L19:L25,"=3")*3+COUNTIF(L19:L25,"3+VR")*3+COUNTIF(L19:L25,"3+VL")*3+COUNTIF(L19:L25,"VR+3")*3+COUNTIF(L19:L25,"VL+3")*3) | D3: =(COUNTIF(D8:D16,"=1")*1+COUNTIF(D8:D16,"1+VR")*1+COUNTIF(D8:D16,"1+VL")*1+COUNTIF(D8:D16,"1+VR+VL")*1+COUNTIF(D8:D16,"VR+1")*1+COUNTIF(D8:D16,"VL+1")*1+COUNTIF(D8:D16,"=2")*2+COUNTIF(D8:D16,"2+VR")*2+COUNTIF(D8:D16,"2+VL")*2+COUNTIF(D8:D16,"VR+2")*2+COUNTIF(D8:D16,"VL+2")*2+COUNTIF(D8:D16,"=3")*3+COUNTIF(D8:D16,"3+VR")*3+COUNTIF(D8:D16,"3+VL")*3+COUNTIF(D8:D16,"VR+3")*3+COUNTIF(D8:D16,"VL+3")*3)+(COUNTIF(D21:D25,"=1")*1+COUNTIF(D21:D25,"1+VR")*1+COUNTIF(D21:D25,"1+VL")*1+COUNTIF(D21:D25,"1+VR+VL")*1+COUNTIF(D21:D25,"VR+1")*1+COUNTIF(D21:D25,"VL+1")*1+COUNTIF(D21:D25,"=2")*2+COUNTIF(D21:D25,"2+VR")*2+COUNTIF(D21:D25,"2+VL")*2+COUNTIF(D21:D25,"VR+2")*2+COUNTIF(D21:D25,"VL+2")*2+COUNTIF(D21:D25,"=3")*3+COUNTIF(D21:D25,"3+VR")*3+COUNTIF(D21:D25,"3+VL")*3+COUNTIF(D21:D25,"VR+3")*3+COUNTIF(D21:D25,"VL+3")*3)+(COUNTIF(D30:D37,"=1")*1+COUNTIF(D30:D37,"1+VR")*1+COUNTIF(D30:D37,"1+VL")*1+COUNTIF(D30:D37,"1+VR+VL")*1+COUNTIF(D30:D37,"VR+1")*1+COUNTIF(D30:D37,"VL+1")*1+COUNTIF(D30:D37,"=2")*2+COUNTIF(D30:D37,"2+VR")*2+COUNTIF(D30:D37,"2+VL")*2+COUNTIF(D30:D37,"VR+2")*2+COUNTIF(D30:D37,"VL+2")*2+COUNTIF(D30:D37,"=3")*3+COUNTIF(D30:D37,"3+VR")*3+COUNTIF(D30:D37,"3+VL")*3+COUNTIF(D30:D37,"VR+3")*3+COUNTIF(D30:D37,"VL+3")*3)+(COUNTIF(D42:D50,"=1")*1+COUNTIF(D42:D50,"1+VR")*1+COUNTIF(D42:D50,"1+VL")*1+COUNTIF(D42:D50,"1+VR+VL")*1+COUNTIF(D42:D50,"VR+1")*1+COUNTIF(D42:D50,"VL+1")*1+COUNTIF(D42:D50,"=2")*2+COUNTIF(D42:D50,"2+VR")*2+COUNTIF(D42:D50,"2+VL")*2+COUNTIF(D42:D50,"VR+2")*2+COUNTIF(D42:D50,"VL+2")*2+COUNTIF(D42:D50,"=3")*3+COUNTIF(D42:D50,"3+VR")*3+COUNTIF(D42:D50,"3+VL")*3+COUNTIF(D42:D50,"VR+3")*3+COUNTIF(D42:D50,"VL+3")*3)+(COUNTIF(D55:D63,"=1")*1+COUNTIF(D55:D63,"1+VR")*1+COUNTIF(D55:D63,"1+VL")*1+COUNTIF(D55:D63,"1+VR+VL")*1+COUNTIF(D55:D63,"VR+1")*1+COUNTIF(D55:D63,"VL+1")*1+COUNTIF(D55:D63,"=2")*2+COUNTIF(D55:D63,"2+VR")*2+COUNTIF(D55:D63,"2+VL")*2+COUNTIF(D55:D63,"VR+2")*2+COUNTIF(D55:D63,"VL+2")*2+COUNTIF(D55:D63,"=3")*3+COUNTIF(D55:D63,"3+VR")*3+COUNTIF(D55:D63,"3+VL")*3+COUNTIF(D55:D63,"VR+3")*3+COUNTIF(D55:D63,"VL+3")*3)+(COUNTIF(D68:D75,"=1")*1+COUNTIF(D68:D75,"1+VR")*1+COUNTIF(D68:D75,"1+VL")*1+COUNTIF(D68:D75,"1+VR+VL")*1+COUNTIF(D68:D75,"VR+1")*1+COUNTIF(D68:D75,"VL+1")*1+COUNTIF(D68:D75,"=2")*2+COUNTIF(D68:D75,"2+VR")*2+COUNTIF(D68:D75,"2+VL")*2+COUNTIF(D68:D75,"VR+2")*2+COUNTIF(D68:D75,"VL+2")*2+COUNTIF(D68:D75,"=3")*3+COUNTIF(D68:D75,"3+VR")*3+COUNTIF(D68:D75,"3+VL")*3+COUNTIF(D68:D75,"VR+3")*3+COUNTIF(D68:D75,"VL+3")*3)+(COUNTIF(D80:D83,"=1")*1+COUNTIF(D80:D83,"1+VR")*1+COUNTIF(D80:D83,"1+VL")*1+COUNTIF(D80:D83,"1+VR+VL")*1+COUNTIF(D80:D83,"VR+1")*1+COUNTIF(D80:D83,"VL+1")*1+COUNTIF(D80:D83,"=2")*2+COUNTIF(D80:D83,"2+VR")*2+COUNTIF(D80:D83,"2+VL")*2+COUNTIF(D80:D83,"VR+2")*2+COUNTIF(D80:D83,"VL+2")*2+COUNTIF(D80:D83,"=3")*3+COUNTIF(D80:D83,"3+VR")*3+COUNTIF(D80:D83,"3+VL")*3+COUNTIF(D80:D83,"VR+3")*3+COUNTIF(D80:D83,"VL+3")*3)+(COUNTIF(D88:D91,"=1")*1+COUNTIF(D88:D91,"1+VR")*1+COUNTIF(D88:D91,"1+VL")*1+COUNTIF(D88:D91,"1+VR+VL")*1+COUNTIF(D88:D91,"VR+1")*1+COUNTIF(D88:D91,"VL+1")*1+COUNTIF(D88:D91,"=2")*2+COUNTIF(D88:D91,"2+VR")*2+COUNTIF(D88:D91,"2+VL")*2+COUNTIF(D88:D91,"VR+2")*2+COUNTIF(D88:D91,"VL+2")*2+COUNTIF(D88:D91,"=3")*3+COUNTIF(D88:D91,"3+VR")*3+COUNTIF(D88:D91,"3+VL")*3+COUNTIF(D88:D91,"VR+3")*3+COUNTIF(D88:D91,"VL+3")*3)+(COUNTIF(D96:D105,"=1")*1+COUNTIF(D96:D105,"1+VR")*1+COUNTIF(D96:D105,"1+VL")*1+COUNTIF(D96:D105,"1+VR+VL")*1+COUNTIF(D96:D105,"VR+1")*1+COUNTIF(D96:D105,"VL+1")*1+COUNTIF(D96:D105,"=2")*2+COUNTIF(D96:D105,"2+VR")*2+COUNTIF(D96:D105,"2+VL")*2+COUNTIF(D96:D105,"VR+2")*2+COUNTIF(D96:D105,"VL+2")*2+COUNTIF(D96:D105,"=3")*3+COUNTIF(D96:D105,"3+VR")*3+COUNTIF(D96:D105,"3+VL")*3+COUNTIF(D96:D105,"VR+3")*3+COUNTIF(D96:D105,"VL+3")*3)+(COUNTIF(D110:D115,"=1")*1+COUNTIF(D110:D115,"1+VR")*1+COUNTIF(D110:D115,"1+VL")*1+COUNTIF(D110:D115,"1+VR+VL")*1+COUNTIF(D110:D115,"VR+1")*1+COUNTIF(D110:D115,"VL+1")*1+COUNTIF(D110:D115,"=2")*2+COUNTIF(D110:D115,"2+VR")*2+COUNTIF(D110:D115,"2+VL")*2+COUNTIF(D110:D115,"VR+2")*2+COUNTIF(D110:D115,"VL+2")*2+COUNTIF(D110:D115,"=3")*3+COUNTIF(D110:D115,"3+VR")*3+COUNTIF(D110:D115,"3+VL")*3+COUNTIF(D110:D115,"VR+3")*3+COUNTIF(D110:D115,"VL+3")*3)+(COUNTIF(D120:D125,"=1")*1+COUNTIF(D120:D125,"1+VR")*1+COUNTIF(D120:D125,"1+VL")*1+COUNTIF(D120:D125,"1+VR+VL")*1+COUNTIF(D120:D125,"VR+1")*1+COUNTIF(D120:D125,"VL+1")*1+COUNTIF(D120:D125,"=2")*2+COUNTIF(D120:D125,"2+VR")*2+COUNTIF(D120:D125,"2+VL")*2+COUNTIF(D120:D125,"VR+2")*2+COUNTIF(D120:D125,"VL+2")*2+COUNTIF(D120:D125,"=3")*3+COUNTIF(D120:D125,"3+VR")*3+COUNTIF(D120:D125,"3+VL")*3+COUNTIF(D120:D125,"VR+3")*3+COUNTIF(D120:D125,"VL+3")*3)+(COUNTIF(D130:D131,"=1")*1+COUNTIF(D130:D131,"1+VR")*1+COUNTIF(D130:D131,"1+VL")*1+COUNTIF(D130:D131,"1+VR+VL")*1+COUNTIF(D130:D131,"VR+1")*1+COUNTIF(D130:D131,"VL+1")*1+COUNTIF(D130:D131,"=2")*2+COUNTIF(D130:D131,"2+VR")*2+COUNTIF(D130:D131,"2+VL")*2+COUNTIF(D130:D131,"VR+2")*2+COUNTIF(D130:D131,"VL+2")*2+COUNTIF(D130:D131,"=3")*3+COUNTIF(D130:D131,"3+VR")*3+COUNTIF(D130:D131,"3+VL")*3+COUNTIF(D130:D131,"VR+3")*3+COUNTIF(D130:D131,"VL+3")*3)+(COUNTIF(D136:D137,"=1")*1+COUNTIF(D136:D137,"1+VR")*1+COUNTIF(D136:D137,"1+VL")*1+COUNTIF(D136:D137,"1+VR+VL")*1+COUNTIF(D136:D137,"VR+1")*1+COUNTIF(D136:D137,"VL+1")*1+COUNTIF(D136:D137,"=2")*2+COUNTIF(D136:D137,"2+VR")*2+COUNTIF(D136:D137,"2+VL")*2+COUNTIF(D136:D137,"VR+2")*2+COUNTIF(D136:D137,"VL+2")*2+COUNTIF(D136:D137,"=3")*3+COUNTIF(D136:D137,"3+VR")*3+COUNTIF(D136:D137,"3+VL")*3+COUNTIF(D136:D137,"VR+3")*3+COUNTIF(D136:D137,"VL+3")*3)+(COUNTIF(D142:D147,"=1")*1+COUNTIF(D142:D147,"1+VR")*1+COUNTIF(D142:D147,"1+VL")*1+COUNTIF(D142:D147,"1+VR+VL")*1+COUNTIF(D142:D147,"VR+1")*1+COUNTIF(D142:D147,"VL+1")*1+COUNTIF(D142:D147,"=2")*2+COUNTIF(D142:D147,"2+VR")*2+COUNTIF(D142:D147,"2+VL")*2+COUNTIF(D142:D147,"VR+2")*2+COUNTIF(D142:D147,"VL+2")*2+COUNTIF(D142:D147,"=3")*3+COUNTIF(D142:D147,"3+VR")*3+COUNTIF(D142:D147,"3+VL")*3+COUNTIF(D142:D147,"VR+3")*3+COUNTIF(D142:D147,"VL+3")*3)+(COUNTIF(D152:D156,"=1")*1+COUNTIF(D152:D156,"1+VR")*1+COUNTIF(D152:D156,"1+VL")*1+COUNTIF(D152:D156,"1+VR+VL")*1+COUNTIF(D152:D156,"VR+1")*1+COUNTIF(D152:D156,"VL+1")*1+COUNTIF(D152:D156,"=2")*2+COUNTIF(D152:D156,"2+VR")*2+COUNTIF(D152:D156,"2+VL")*2+COUNTIF(D152:D156,"VR+2")*2+COUNTIF(D152:D156,"VL+2")*2+COUNTIF(D152:D156,"=3")*3+COUNTIF(D152:D156,"3+VR")*3+COUNTIF(D152:D156,"3+VL")*3+COUNTIF(D152:D156,"VR+3")*3+COUNTIF(D152:D156,"VL+3")*3)+(COUNTIF(D161:D163,"=1")*1+COUNTIF(D161:D163,"1+VR")*1+COUNTIF(D161:D163,"1+VL")*1+COUNTIF(D161:D163,"1+VR+VL")*1+COUNTIF(D161:D163,"VR+1")*1+COUNTIF(D161:D163,"VL+1")*1+COUNTIF(D161:D163,"=2")*2+COUNTIF(D161:D163,"2+VR")*2+COUNTIF(D161:D163,"2+VL")*2+COUNTIF(D161:D163,"VR+2")*2+COUNTIF(D161:D163,"VL+2")*2+COUNTIF(D161:D163,"=3")*3+COUNTIF(D161:D163,"3+VR")*3+COUNTIF(D161:D163,"3+VL")*3+COUNTIF(D161:D163,"VR+3")*3+COUNTIF(D161:D163,"VL+3")*3)+(COUNTIF(D168:D168,"=1")*1+COUNTIF(D168:D168,"1+VR")*1+COUNTIF(D168:D168,"1+VL")*1+COUNTIF(D168:D168,"1+VR+VL")*1+COUNTIF(D168:D168,"VR+1")*1+COUNTIF(D168:D168,"VL+1")*1+COUNTIF(D168:D168,"=2")*2+COUNTIF(D168:D168,"2+VR")*2+COUNTIF(D168:D168,"2+VL")*2+COUNTIF(D168:D168,"VR+2")*2+COUNTIF(D168:D168,"VL+2")*2+COUNTIF(D168:D168,"=3")*3+COUNTIF(D168:D168,"3+VR")*3+COUNTIF(D168:D168,"3+VL")*3+COUNTIF(D168:D168,"VR+3")*3+COUNTIF(D168:D168,"VL+3")*3)+(COUNTIF(M8:M14,"=1")*1+COUNTIF(M8:M14,"1+VR")*1+COUNTIF(M8:M14,"1+VL")*1+COUNTIF(M8:M14,"1+VR+VL")*1+COUNTIF(M8:M14,"VR+1")*1+COUNTIF(M8:M14,"VL+1")*1+COUNTIF(M8:M14,"=2")*2+COUNTIF(M8:M14,"2+VR")*2+COUNTIF(M8:M14,"2+VL")*2+COUNTIF(M8:M14,"VR+2")*2+COUNTIF(M8:M14,"VL+2")*2+COUNTIF(M8:M14,"=3")*3+COUNTIF(M8:M14,"3+VR")*3+COUNTIF(M8:M14,"3+VL")*3+COUNTIF(M8:M14,"VR+3")*3+COUNTIF(M8:M14,"VL+3")*3)+(COUNTIF(M19:M25,"=1")*1+COUNTIF(M19:M25,"1+VR")*1+COUNTIF(M19:M25,"1+VL")*1+COUNTIF(M19:M25,"1+VR+VL")*1+COUNTIF(M19:M25,"VR+1")*1+COUNTIF(M19:M25,"VL+1")*1+COUNTIF(M19:M25,"=2")*2+COUNTIF(M19:M25,"2+VR")*2+COUNTIF(M19:M25,"2+VL")*2+COUNTIF(M19:M25,"VR+2")*2+COUNTIF(M19:M25,"VL+2")*2+COUNTIF(M19:M25,"=3")*3+COUNTIF(M19:M25,"3+VR")*3+COUNTIF(M19:M25,"3+VL")*3+COUNTIF(M19:M25,"VR+3")*3+COUNTIF(M19:M25,"VL+3")*3) | E3: =(COUNTIF(E8:E16,"=1")*1+COUNTIF(E8:E16,"1+VR")*1+COUNTIF(E8:E16,"1+VL")*1+COUNTIF(E8:E16,"1+VR+VL")*1+COUNTIF(E8:E16,"VR+1")*1+COUNTIF(E8:E16,"VL+1")*1+COUNTIF(E8:E16,"=2")*2+COUNTIF(E8:E16,"2+VR")*2+COUNTIF(E8:E16,"2+VL")*2+COUNTIF(E8:E16,"VR+2")*2+COUNTIF(E8:E16,"VL+2")*2+COUNTIF(E8:E16,"=3")*3+COUNTIF(E8:E16,"3+VR")*3+COUNTIF(E8:E16,"3+VL")*3+COUNTIF(E8:E16,"VR+3")*3+COUNTIF(E8:E16,"VL+3")*3)+(COUNTIF(E21:E25,"=1")*1+COUNTIF(E21:E25,"1+VR")*1+COUNTIF(E21:E25,"1+VL")*1+COUNTIF(E21:E25,"1+VR+VL")*1+COUNTIF(E21:E25,"VR+1")*1+COUNTIF(E21:E25,"VL+1")*1+COUNTIF(E21:E25,"=2")*2+COUNTIF(E21:E25,"2+VR")*2+COUNTIF(E21:E25,"2+VL")*2+COUNTIF(E21:E25,"VR+2")*2+COUNTIF(E21:E25,"VL+2")*2+COUNTIF(E21:E25,"=3")*3+COUNTIF(E21:E25,"3+VR")*3+COUNTIF(E21:E25,"3+VL")*3+COUNTIF(E21:E25,"VR+3")*3+COUNTIF(E21:E25,"VL+3")*3)+(COUNTIF(E30:E37,"=1")*1+COUNTIF(E30:E37,"1+VR")*1+COUNTIF(E30:E37,"1+VL")*1+COUNTIF(E30:E37,"1+VR+VL")*1+COUNTIF(E30:E37,"VR+1")*1+COUNTIF(E30:E37,"VL+1")*1+COUNTIF(E30:E37,"=2")*2+COUNTIF(E30:E37,"2+VR")*2+COUNTIF(E30:E37,"2+VL")*2+COUNTIF(E30:E37,"VR+2")*2+COUNTIF(E30:E37,"VL+2")*2+COUNTIF(E30:E37,"=3")*3+COUNTIF(E30:E37,"3+VR")*3+COUNTIF(E30:E37,"3+VL")*3+COUNTIF(E30:E37,"VR+3")*3+COUNTIF(E30:E37,"VL+3")*3)+(COUNTIF(E42:E50,"=1")*1+COUNTIF(E42:E50,"1+VR")*1+COUNTIF(E42:E50,"1+VL")*1+COUNTIF(E42:E50,"1+VR+VL")*1+COUNTIF(E42:E50,"VR+1")*1+COUNTIF(E42:E50,"VL+1")*1+COUNTIF(E42:E50,"=2")*2+COUNTIF(E42:E50,"2+VR")*2+COUNTIF(E42:E50,"2+VL")*2+COUNTIF(E42:E50,"VR+2")*2+COUNTIF(E42:E50,"VL+2")*2+COUNTIF(E42:E50,"=3")*3+COUNTIF(E42:E50,"3+VR")*3+COUNTIF(E42:E50,"3+VL")*3+COUNTIF(E42:E50,"VR+3")*3+COUNTIF(E42:E50,"VL+3")*3)+(COUNTIF(E55:E63,"=1")*1+COUNTIF(E55:E63,"1+VR")*1+COUNTIF(E55:E63,"1+VL")*1+COUNTIF(E55:E63,"1+VR+VL")*1+COUNTIF(E55:E63,"VR+1")*1+COUNTIF(E55:E63,"VL+1")*1+COUNTIF(E55:E63,"=2")*2+COUNTIF(E55:E63,"2+VR")*2+COUNTIF(E55:E63,"2+VL")*2+COUNTIF(E55:E63,"VR+2")*2+COUNTIF(E55:E63,"VL+2")*2+COUNTIF(E55:E63,"=3")*3+COUNTIF(E55:E63,"3+VR")*3+COUNTIF(E55:E63,"3+VL")*3+COUNTIF(E55:E63,"VR+3")*3+COUNTIF(E55:E63,"VL+3")*3)+(COUNTIF(E68:E75,"=1")*1+COUNTIF(E68:E75,"1+VR")*1+COUNTIF(E68:E75,"1+VL")*1+COUNTIF(E68:E75,"1+VR+VL")*1+COUNTIF(E68:E75,"VR+1")*1+COUNTIF(E68:E75,"VL+1")*1+COUNTIF(E68:E75,"=2")*2+COUNTIF(E68:E75,"2+VR")*2+COUNTIF(E68:E75,"2+VL")*2+COUNTIF(E68:E75,"VR+2")*2+COUNTIF(E68:E75,"VL+2")*2+COUNTIF(E68:E75,"=3")*3+COUNTIF(E68:E75,"3+VR")*3+COUNTIF(E68:E75,"3+VL")*3+COUNTIF(E68:E75,"VR+3")*3+COUNTIF(E68:E75,"VL+3")*3)+(COUNTIF(E80:E83,"=1")*1+COUNTIF(E80:E83,"1+VR")*1+COUNTIF(E80:E83,"1+VL")*1+COUNTIF(E80:E83,"1+VR+VL")*1+COUNTIF(E80:E83,"VR+1")*1+COUNTIF(E80:E83,"VL+1")*1+COUNTIF(E80:E83,"=2")*2+COUNTIF(E80:E83,"2+VR")*2+COUNTIF(E80:E83,"2+VL")*2+COUNTIF(E80:E83,"VR+2")*2+COUNTIF(E80:E83,"VL+2")*2+COUNTIF(E80:E83,"=3")*3+COUNTIF(E80:E83,"3+VR")*3+COUNTIF(E80:E83,"3+VL")*3+COUNTIF(E80:E83,"VR+3")*3+COUNTIF(E80:E83,"VL+3")*3)+(COUNTIF(E88:E91,"=1")*1+COUNTIF(E88:E91,"1+VR")*1+COUNTIF(E88:E91,"1+VL")*1+COUNTIF(E88:E91,"1+VR+VL")*1+COUNTIF(E88:E91,"VR+1")*1+COUNTIF(E88:E91,"VL+1")*1+COUNTIF(E88:E91,"=2")*2+COUNTIF(E88:E91,"2+VR")*2+COUNTIF(E88:E91,"2+VL")*2+COUNTIF(E88:E91,"VR+2")*2+COUNTIF(E88:E91,"VL+2")*2+COUNTIF(E88:E91,"=3")*3+COUNTIF(E88:E91,"3+VR")*3+COUNTIF(E88:E91,"3+VL")*3+COUNTIF(E88:E91,"VR+3")*3+COUNTIF(E88:E91,"VL+3")*3)+(COUNTIF(E96:E105,"=1")*1+COUNTIF(E96:E105,"1+VR")*1+COUNTIF(E96:E105,"1+VL")*1+COUNTIF(E96:E105,"1+VR+VL")*1+COUNTIF(E96:E105,"VR+1")*1+COUNTIF(E96:E105,"VL+1")*1+COUNTIF(E96:E105,"=2")*2+COUNTIF(E96:E105,"2+VR")*2+COUNTIF(E96:E105,"2+VL")*2+COUNTIF(E96:E105,"VR+2")*2+COUNTIF(E96:E105,"VL+2")*2+COUNTIF(E96:E105,"=3")*3+COUNTIF(E96:E105,"3+VR")*3+COUNTIF(E96:E105,"3+VL")*3+COUNTIF(E96:E105,"VR+3")*3+COUNTIF(E96:E105,"VL+3")*3)+(COUNTIF(E110:E115,"=1")*1+COUNTIF(E110:E115,"1+VR")*1+COUNTIF(E110:E115,"1+VL")*1+COUNTIF(E110:E115,"1+VR+VL")*1+COUNTIF(E110:E115,"VR+1")*1+COUNTIF(E110:E115,"VL+1")*1+COUNTIF(E110:E115,"=2")*2+COUNTIF(E110:E115,"2+VR")*2+COUNTIF(E110:E115,"2+VL")*2+COUNTIF(E110:E115,"VR+2")*2+COUNTIF(E110:E115,"VL+2")*2+COUNTIF(E110:E115,"=3")*3+COUNTIF(E110:E115,"3+VR")*3+COUNTIF(E110:E115,"3+VL")*3+COUNTIF(E110:E115,"VR+3")*3+COUNTIF(E110:E115,"VL+3")*3)+(COUNTIF(E120:E125,"=1")*1+COUNTIF(E120:E125,"1+VR")*1+COUNTIF(E120:E125,"1+VL")*1+COUNTIF(E120:E125,"1+VR+VL")*1+COUNTIF(E120:E125,"VR+1")*1+COUNTIF(E120:E125,"VL+1")*1+COUNTIF(E120:E125,"=2")*2+COUNTIF(E120:E125,"2+VR")*2+COUNTIF(E120:E125,"2+VL")*2+COUNTIF(E120:E125,"VR+2")*2+COUNTIF(E120:E125,"VL+2")*2+COUNTIF(E120:E125,"=3")*3+COUNTIF(E120:E125,"3+VR")*3+COUNTIF(E120:E125,"3+VL")*3+COUNTIF(E120:E125,"VR+3")*3+COUNTIF(E120:E125,"VL+3")*3)+(COUNTIF(E130:E131,"=1")*1+COUNTIF(E130:E131,"1+VR")*1+COUNTIF(E130:E131,"1+VL")*1+COUNTIF(E130:E131,"1+VR+VL")*1+COUNTIF(E130:E131,"VR+1")*1+COUNTIF(E130:E131,"VL+1")*1+COUNTIF(E130:E131,"=2")*2+COUNTIF(E130:E131,"2+VR")*2+COUNTIF(E130:E131,"2+VL")*2+COUNTIF(E130:E131,"VR+2")*2+COUNTIF(E130:E131,"VL+2")*2+COUNTIF(E130:E131,"=3")*3+COUNTIF(E130:E131,"3+VR")*3+COUNTIF(E130:E131,"3+VL")*3+COUNTIF(E130:E131,"VR+3")*3+COUNTIF(E130:E131,"VL+3")*3)+(COUNTIF(E136:E137,"=1")*1+COUNTIF(E136:E137,"1+VR")*1+COUNTIF(E136:E137,"1+VL")*1+COUNTIF(E136:E137,"1+VR+VL")*1+COUNTIF(E136:E137,"VR+1")*1+COUNTIF(E136:E137,"VL+1")*1+COUNTIF(E136:E137,"=2")*2+COUNTIF(E136:E137,"2+VR")*2+COUNTIF(E136:E137,"2+VL")*2+COUNTIF(E136:E137,"VR+2")*2+COUNTIF(E136:E137,"VL+2")*2+COUNTIF(E136:E137,"=3")*3+COUNTIF(E136:E137,"3+VR")*3+COUNTIF(E136:E137,"3+VL")*3+COUNTIF(E136:E137,"VR+3")*3+COUNTIF(E136:E137,"VL+3")*3)+(COUNTIF(E142:E147,"=1")*1+COUNTIF(E142:E147,"1+VR")*1+COUNTIF(E142:E147,"1+VL")*1+COUNTIF(E142:E147,"1+VR+VL")*1+COUNTIF(E142:E147,"VR+1")*1+COUNTIF(E142:E147,"VL+1")*1+COUNTIF(E142:E147,"=2")*2+COUNTIF(E142:E147,"2+VR")*2+COUNTIF(E142:E147,"2+VL")*2+COUNTIF(E142:E147,"VR+2")*2+COUNTIF(E142:E147,"VL+2")*2+COUNTIF(E142:E147,"=3")*3+COUNTIF(E142:E147,"3+VR")*3+COUNTIF(E142:E147,"3+VL")*3+COUNTIF(E142:E147,"VR+3")*3+COUNTIF(E142:E147,"VL+3")*3)+(COUNTIF(E152:E156,"=1")*1+COUNTIF(E152:E156,"1+VR")*1+COUNTIF(E152:E156,"1+VL")*1+COUNTIF(E152:E156,"1+VR+VL")*1+COUNTIF(E152:E156,"VR+1")*1+COUNTIF(E152:E156,"VL+1")*1+COUNTIF(E152:E156,"=2")*2+COUNTIF(E152:E156,"2+VR")*2+COUNTIF(E152:E156,"2+VL")*2+COUNTIF(E152:E156,"VR+2")*2+COUNTIF(E152:E156,"VL+2")*2+COUNTIF(E152:E156,"=3")*3+COUNTIF(E152:E156,"3+VR")*3+COUNTIF(E152:E156,"3+VL")*3+COUNTIF(E152:E156,"VR+3")*3+COUNTIF(E152:E156,"VL+3")*3)+(COUNTIF(E161:E163,"=1")*1+COUNTIF(E161:E163,"1+VR")*1+COUNTIF(E161:E163,"1+VL")*1+COUNTIF(E161:E163,"1+VR+VL")*1+COUNTIF(E161:E163,"VR+1")*1+COUNTIF(E161:E163,"VL+1")*1+COUNTIF(E161:E163,"=2")*2+COUNTIF(E161:E163,"2+VR")*2+COUNTIF(E161:E163,"2+VL")*2+COUNTIF(E161:E163,"VR+2")*2+COUNTIF(E161:E163,"VL+2")*2+COUNTIF(E161:E163,"=3")*3+COUNTIF(E161:E163,"3+VR")*3+COUNTIF(E161:E163,"3+VL")*3+COUNTIF(E161:E163,"VR+3")*3+COUNTIF(E161:E163,"VL+3")*3)+(COUNTIF(E168:E168,"=1")*1+COUNTIF(E168:E168,"1+VR")*1+COUNTIF(E168:E168,"1+VL")*1+COUNTIF(E168:E168,"1+VR+VL")*1+COUNTIF(E168:E168,"VR+1")*1+COUNTIF(E168:E168,"VL+1")*1+COUNTIF(E168:E168,"=2")*2+COUNTIF(E168:E168,"2+VR")*2+COUNTIF(E168:E168,"2+VL")*2+COUNTIF(E168:E168,"VR+2")*2+COUNTIF(E168:E168,"VL+2")*2+COUNTIF(E168:E168,"=3")*3+COUNTIF(E168:E168,"3+VR")*3+COUNTIF(E168:E168,"3+VL")*3+COUNTIF(E168:E168,"VR+3")*3+COUNTIF(E168:E168,"VL+3")*3)+(COUNTIF(N8:N14,"=1")*1+COUNTIF(N8:N14,"1+VR")*1+COUNTIF(N8:N14,"1+VL")*1+COUNTIF(N8:N14,"1+VR+VL")*1+COUNTIF(N8:N14,"VR+1")*1+COUNTIF(N8:N14,"VL+1")*1+COUNTIF(N8:N14,"=2")*2+COUNTIF(N8:N14,"2+VR")*2+COUNTIF(N8:N14,"2+VL")*2+COUNTIF(N8:N14,"VR+2")*2+COUNTIF(N8:N14,"VL+2")*2+COUNTIF(N8:N14,"=3")*3+COUNTIF(N8:N14,"3+VR")*3+COUNTIF(N8:N14,"3+VL")*3+COUNTIF(N8:N14,"VR+3")*3+COUNTIF(N8:N14,"VL+3")*3)+(COUNTIF(N19:N25,"=1")*1+COUNTIF(N19:N25,"1+VR")*1+COUNTIF(N19:N25,"1+VL")*1+COUNTIF(N19:N25,"1+VR+VL")*1+COUNTIF(N19:N25,"VR+1")*1+COUNTIF(N19:N25,"VL+1")*1+COUNTIF(N19:N25,"=2")*2+COUNTIF(N19:N25,"2+VR")*2+COUNTIF(N19:N25,"2+VL")*2+COUNTIF(N19:N25,"VR+2")*2+COUNTIF(N19:N25,"VL+2")*2+COUNTIF(N19:N25,"=3")*3+COUNTIF(N19:N25,"3+VR")*3+COUNTIF(N19:N25,"3+VL")*3+COUNTIF(N19:N25,"VR+3")*3+COUNTIF(N19:N25,"VL+3")*3) | F3: =(COUNTIF(F8:F16,"=1")*1+COUNTIF(F8:F16,"1+VR")*1+COUNTIF(F8:F16,"1+VL")*1+COUNTIF(F8:F16,"1+VR+VL")*1+COUNTIF(F8:F16,"VR+1")*1+COUNTIF(F8:F16,"VL+1")*1+COUNTIF(F8:F16,"=2")*2+COUNTIF(F8:F16,"2+VR")*2+COUNTIF(F8:F16,"2+VL")*2+COUNTIF(F8:F16,"VR+2")*2+COUNTIF(F8:F16,"VL+2")*2+COUNTIF(F8:F16,"=3")*3+COUNTIF(F8:F16,"3+VR")*3+COUNTIF(F8:F16,"3+VL")*3+COUNTIF(F8:F16,"VR+3")*3+COUNTIF(F8:F16,"VL+3")*3)+(COUNTIF(F21:F25,"=1")*1+COUNTIF(F21:F25,"1+VR")*1+COUNTIF(F21:F25,"1+VL")*1+COUNTIF(F21:F25,"1+VR+VL")*1+COUNTIF(F21:F25,"VR+1")*1+COUNTIF(F21:F25,"VL+1")*1+COUNTIF(F21:F25,"=2")*2+COUNTIF(F21:F25,"2+VR")*2+COUNTIF(F21:F25,"2+VL")*2+COUNTIF(F21:F25,"VR+2")*2+COUNTIF(F21:F25,"VL+2")*2+COUNTIF(F21:F25,"=3")*3+COUNTIF(F21:F25,"3+VR")*3+COUNTIF(F21:F25,"3+VL")*3+COUNTIF(F21:F25,"VR+3")*3+COUNTIF(F21:F25,"VL+3")*3)+(COUNTIF(F30:F37,"=1")*1+COUNTIF(F30:F37,"1+VR")*1+COUNTIF(F30:F37,"1+VL")*1+COUNTIF(F30:F37,"1+VR+VL")*1+COUNTIF(F30:F37,"VR+1")*1+COUNTIF(F30:F37,"VL+1")*1+COUNTIF(F30:F37,"=2")*2+COUNTIF(F30:F37,"2+VR")*2+COUNTIF(F30:F37,"2+VL")*2+COUNTIF(F30:F37,"VR+2")*2+COUNTIF(F30:F37,"VL+2")*2+COUNTIF(F30:F37,"=3")*3+COUNTIF(F30:F37,"3+VR")*3+COUNTIF(F30:F37,"3+VL")*3+COUNTIF(F30:F37,"VR+3")*3+COUNTIF(F30:F37,"VL+3")*3)+(COUNTIF(F42:F50,"=1")*1+COUNTIF(F42:F50,"1+VR")*1+COUNTIF(F42:F50,"1+VL")*1+COUNTIF(F42:F50,"1+VR+VL")*1+COUNTIF(F42:F50,"VR+1")*1+COUNTIF(F42:F50,"VL+1")*1+COUNTIF(F42:F50,"=2")*2+COUNTIF(F42:F50,"2+VR")*2+COUNTIF(F42:F50,"2+VL")*2+COUNTIF(F42:F50,"VR+2")*2+COUNTIF(F42:F50,"VL+2")*2+COUNTIF(F42:F50,"=3")*3+COUNTIF(F42:F50,"3+VR")*3+COUNTIF(F42:F50,"3+VL")*3+COUNTIF(F42:F50,"VR+3")*3+COUNTIF(F42:F50,"VL+3")*3)+(COUNTIF(F55:F63,"=1")*1+COUNTIF(F55:F63,"1+VR")*1+COUNTIF(F55:F63,"1+VL")*1+COUNTIF(F55:F63,"1+VR+VL")*1+COUNTIF(F55:F63,"VR+1")*1+COUNTIF(F55:F63,"VL+1")*1+COUNTIF(F55:F63,"=2")*2+COUNTIF(F55:F63,"2+VR")*2+COUNTIF(F55:F63,"2+VL")*2+COUNTIF(F55:F63,"VR+2")*2+COUNTIF(F55:F63,"VL+2")*2+COUNTIF(F55:F63,"=3")*3+COUNTIF(F55:F63,"3+VR")*3+COUNTIF(F55:F63,"3+VL")*3+COUNTIF(F55:F63,"VR+3")*3+COUNTIF(F55:F63,"VL+3")*3)+(COUNTIF(F68:F75,"=1")*1+COUNTIF(F68:F75,"1+VR")*1+COUNTIF(F68:F75,"1+VL")*1+COUNTIF(F68:F75,"1+VR+VL")*1+COUNTIF(F68:F75,"VR+1")*1+COUNTIF(F68:F75,"VL+1")*1+COUNTIF(F68:F75,"=2")*2+COUNTIF(F68:F75,"2+VR")*2+COUNTIF(F68:F75,"2+VL")*2+COUNTIF(F68:F75,"VR+2")*2+COUNTIF(F68:F75,"VL+2")*2+COUNTIF(F68:F75,"=3")*3+COUNTIF(F68:F75,"3+VR")*3+COUNTIF(F68:F75,"3+VL")*3+COUNTIF(F68:F75,"VR+3")*3+COUNTIF(F68:F75,"VL+3")*3)+(COUNTIF(F80:F83,"=1")*1+COUNTIF(F80:F83,"1+VR")*1+COUNTIF(F80:F83,"1+VL")*1+COUNTIF(F80:F83,"1+VR+VL")*1+COUNTIF(F80:F83,"VR+1")*1+COUNTIF(F80:F83,"VL+1")*1+COUNTIF(F80:F83,"=2")*2+COUNTIF(F80:F83,"2+VR")*2+COUNTIF(F80:F83,"2+VL")*2+COUNTIF(F80:F83,"VR+2")*2+COUNTIF(F80:F83,"VL+2")*2+COUNTIF(F80:F83,"=3")*3+COUNTIF(F80:F83,"3+VR")*3+COUNTIF(F80:F83,"3+VL")*3+COUNTIF(F80:F83,"VR+3")*3+COUNTIF(F80:F83,"VL+3")*3)+(COUNTIF(F88:F91,"=1")*1+COUNTIF(F88:F91,"1+VR")*1+COUNTIF(F88:F91,"1+VL")*1+COUNTIF(F88:F91,"1+VR+VL")*1+COUNTIF(F88:F91,"VR+1")*1+COUNTIF(F88:F91,"VL+1")*1+COUNTIF(F88:F91,"=2")*2+COUNTIF(F88:F91,"2+VR")*2+COUNTIF(F88:F91,"2+VL")*2+COUNTIF(F88:F91,"VR+2")*2+COUNTIF(F88:F91,"VL+2")*2+COUNTIF(F88:F91,"=3")*3+COUNTIF(F88:F91,"3+VR")*3+COUNTIF(F88:F91,"3+VL")*3+COUNTIF(F88:F91,"VR+3")*3+COUNTIF(F88:F91,"VL+3")*3)+(COUNTIF(F96:F105,"=1")*1+COUNTIF(F96:F105,"1+VR")*1+COUNTIF(F96:F105,"1+VL")*1+COUNTIF(F96:F105,"1+VR+VL")*1+COUNTIF(F96:F105,"VR+1")*1+COUNTIF(F96:F105,"VL+1")*1+COUNTIF(F96:F105,"=2")*2+COUNTIF(F96:F105,"2+VR")*2+COUNTIF(F96:F105,"2+VL")*2+COUNTIF(F96:F105,"VR+2")*2+COUNTIF(F96:F105,"VL+2")*2+COUNTIF(F96:F105,"=3")*3+COUNTIF(F96:F105,"3+VR")*3+COUNTIF(F96:F105,"3+VL")*3+COUNTIF(F96:F105,"VR+3")*3+COUNTIF(F96:F105,"VL+3")*3)+(COUNTIF(F110:F115,"=1")*1+COUNTIF(F110:F115,"1+VR")*1+COUNTIF(F110:F115,"1+VL")*1+COUNTIF(F110:F115,"1+VR+VL")*1+COUNTIF(F110:F115,"VR+1")*1+COUNTIF(F110:F115,"VL+1")*1+COUNTIF(F110:F115,"=2")*2+COUNTIF(F110:F115,"2+VR")*2+COUNTIF(F110:F115,"2+VL")*2+COUNTIF(F110:F115,"VR+2")*2+COUNTIF(F110:F115,"VL+2")*2+COUNTIF(F110:F115,"=3")*3+COUNTIF(F110:F115,"3+VR")*3+COUNTIF(F110:F115,"3+VL")*3+COUNTIF(F110:F115,"VR+3")*3+COUNTIF(F110:F115,"VL+3")*3)+(COUNTIF(F120:F125,"=1")*1+COUNTIF(F120:F125,"1+VR")*1+COUNTIF(F120:F125,"1+VL")*1+COUNTIF(F120:F125,"1+VR+VL")*1+COUNTIF(F120:F125,"VR+1")*1+COUNTIF(F120:F125,"VL+1")*1+COUNTIF(F120:F125,"=2")*2+COUNTIF(F120:F125,"2+VR")*2+COUNTIF(F120:F125,"2+VL")*2+COUNTIF(F120:F125,"VR+2")*2+COUNTIF(F120:F125,"VL+2")*2+COUNTIF(F120:F125,"=3")*3+COUNTIF(F120:F125,"3+VR")*3+COUNTIF(F120:F125,"3+VL")*3+COUNTIF(F120:F125,"VR+3")*3+COUNTIF(F120:F125,"VL+3")*3)+(COUNTIF(F130:F131,"=1")*1+COUNTIF(F130:F131,"1+VR")*1+COUNTIF(F130:F131,"1+VL")*1+COUNTIF(F130:F131,"1+VR+VL")*1+COUNTIF(F130:F131,"VR+1")*1+COUNTIF(F130:F131,"VL+1")*1+COUNTIF(F130:F131,"=2")*2+COUNTIF(F130:F131,"2+VR")*2+COUNTIF(F130:F131,"2+VL")*2+COUNTIF(F130:F131,"VR+2")*2+COUNTIF(F130:F131,"VL+2")*2+COUNTIF(F130:F131,"=3")*3+COUNTIF(F130:F131,"3+VR")*3+COUNTIF(F130:F131,"3+VL")*3+COUNTIF(F130:F131,"VR+3")*3+COUNTIF(F130:F131,"VL+3")*3)+(COUNTIF(F136:F137,"=1")*1+COUNTIF(F136:F137,"1+VR")*1+COUNTIF(F136:F137,"1+VL")*1+COUNTIF(F136:F137,"1+VR+VL")*1+COUNTIF(F136:F137,"VR+1")*1+COUNTIF(F136:F137,"VL+1")*1+COUNTIF(F136:F137,"=2")*2+COUNTIF(F136:F137,"2+VR")*2+COUNTIF(F136:F137,"2+VL")*2+COUNTIF(F136:F137,"VR+2")*2+COUNTIF(F136:F137,"VL+2")*2+COUNTIF(F136:F137,"=3")*3+COUNTIF(F136:F137,"3+VR")*3+COUNTIF(F136:F137,"3+VL")*3+COUNTIF(F136:F137,"VR+3")*3+COUNTIF(F136:F137,"VL+3")*3)+(COUNTIF(F142:F147,"=1")*1+COUNTIF(F142:F147,"1+VR")*1+COUNTIF(F142:F147,"1+VL")*1+COUNTIF(F142:F147,"1+VR+VL")*1+COUNTIF(F142:F147,"VR+1")*1+COUNTIF(F142:F147,"VL+1")*1+COUNTIF(F142:F147,"=2")*2+COUNTIF(F142:F147,"2+VR")*2+COUNTIF(F142:F147,"2+VL")*2+COUNTIF(F142:F147,"VR+2")*2+COUNTIF(F142:F147,"VL+2")*2+COUNTIF(F142:F147,"=3")*3+COUNTIF(F142:F147,"3+VR")*3+COUNTIF(F142:F147,"3+VL")*3+COUNTIF(F142:F147,"VR+3")*3+COUNTIF(F142:F147,"VL+3")*3)+(COUNTIF(F152:F156,"=1")*1+COUNTIF(F152:F156,"1+VR")*1+COUNTIF(F152:F156,"1+VL")*1+COUNTIF(F152:F156,"1+VR+VL")*1+COUNTIF(F152:F156,"VR+1")*1+COUNTIF(F152:F156,"VL+1")*1+COUNTIF(F152:F156,"=2")*2+COUNTIF(F152:F156,"2+VR")*2+COUNTIF(F152:F156,"2+VL")*2+COUNTIF(F152:F156,"VR+2")*2+COUNTIF(F152:F156,"VL+2")*2+COUNTIF(F152:F156,"=3")*3+COUNTIF(F152:F156,"3+VR")*3+COUNTIF(F152:F156,"3+VL")*3+COUNTIF(F152:F156,"VR+3")*3+COUNTIF(F152:F156,"VL+3")*3)+(COUNTIF(F161:F163,"=1")*1+COUNTIF(F161:F163,"1+VR")*1+COUNTIF(F161:F163,"1+VL")*1+COUNTIF(F161:F163,"1+VR+VL")*1+COUNTIF(F161:F163,"VR+1")*1+COUNTIF(F161:F163,"VL+1")*1+COUNTIF(F161:F163,"=2")*2+COUNTIF(F161:F163,"2+VR")*2+COUNTIF(F161:F163,"2+VL")*2+COUNTIF(F161:F163,"VR+2")*2+COUNTIF(F161:F163,"VL+2")*2+COUNTIF(F161:F163,"=3")*3+COUNTIF(F161:F163,"3+VR")*3+COUNTIF(F161:F163,"3+VL")*3+COUNTIF(F161:F163,"VR+3")*3+COUNTIF(F161:F163,"VL+3")*3)+(COUNTIF(F168:F168,"=1")*1+COUNTIF(F168:F168,"1+VR")*1+COUNTIF(F168:F168,"1+VL")*1+COUNTIF(F168:F168,"1+VR+VL")*1+COUNTIF(F168:F168,"VR+1")*1+COUNTIF(F168:F168,"VL+1")*1+COUNTIF(F168:F168,"=2")*2+COUNTIF(F168:F168,"2+VR")*2+COUNTIF(F168:F168,"2+VL")*2+COUNTIF(F168:F168,"VR+2")*2+COUNTIF(F168:F168,"VL+2")*2+COUNTIF(F168:F168,"=3")*3+COUNTIF(F168:F168,"3+VR")*3+COUNTIF(F168:F168,"3+VL")*3+COUNTIF(F168:F168,"VR+3")*3+COUNTIF(F168:F168,"VL+3")*3)+(COUNTIF(O8:O14,"=1")*1+COUNTIF(O8:O14,"1+VR")*1+COUNTIF(O8:O14,"1+VL")*1+COUNTIF(O8:O14,"1+VR+VL")*1+COUNTIF(O8:O14,"VR+1")*1+COUNTIF(O8:O14,"VL+1")*1+COUNTIF(O8:O14,"=2")*2+COUNTIF(O8:O14,"2+VR")*2+COUNTIF(O8:O14,"2+VL")*2+COUNTIF(O8:O14,"VR+2")*2+COUNTIF(O8:O14,"VL+2")*2+COUNTIF(O8:O14,"=3")*3+COUNTIF(O8:O14,"3+VR")*3+COUNTIF(O8:O14,"3+VL")*3+COUNTIF(O8:O14,"VR+3")*3+COUNTIF(O8:O14,"VL+3")*3)+(COUNTIF(O19:O25,"=1")*1+COUNTIF(O19:O25,"1+VR")*1+COUNTIF(O19:O25,"1+VL")*1+COUNTIF(O19:O25,"1+VR+VL")*1+COUNTIF(O19:O25,"VR+1")*1+COUNTIF(O19:O25,"VL+1")*1+COUNTIF(O19:O25,"=2")*2+COUNTIF(O19:O25,"2+VR")*2+COUNTIF(O19:O25,"2+VL")*2+COUNTIF(O19:O25,"VR+2")*2+COUNTIF(O19:O25,"VL+2")*2+COUNTIF(O19:O25,"=3")*3+COUNTIF(O19:O25,"3+VR")*3+COUNTIF(O19:O25,"3+VL")*3+COUNTIF(O19:O25,"VR+3")*3+COUNTIF(O19:O25,"VL+3")*3) | G3: =(COUNTIF(G8:G16,"=1")*1+COUNTIF(G8:G16,"1+VR")*1+COUNTIF(G8:G16,"1+VL")*1+COUNTIF(G8:G16,"1+VR+VL")*1+COUNTIF(G8:G16,"VR+1")*1+COUNTIF(G8:G16,"VL+1")*1+COUNTIF(G8:G16,"=2")*2+COUNTIF(G8:G16,"2+VR")*2+COUNTIF(G8:G16,"2+VL")*2+COUNTIF(G8:G16,"VR+2")*2+COUNTIF(G8:G16,"VL+2")*2+COUNTIF(G8:G16,"=3")*3+COUNTIF(G8:G16,"3+VR")*3+COUNTIF(G8:G16,"3+VL")*3+COUNTIF(G8:G16,"VR+3")*3+COUNTIF(G8:G16,"VL+3")*3)+(COUNTIF(G21:G25,"=1")*1+COUNTIF(G21:G25,"1+VR")*1+COUNTIF(G21:G25,"1+VL")*1+COUNTIF(G21:G25,"1+VR+VL")*1+COUNTIF(G21:G25,"VR+1")*1+COUNTIF(G21:G25,"VL+1")*1+COUNTIF(G21:G25,"=2")*2+COUNTIF(G21:G25,"2+VR")*2+COUNTIF(G21:G25,"2+VL")*2+COUNTIF(G21:G25,"VR+2")*2+COUNTIF(G21:G25,"VL+2")*2+COUNTIF(G21:G25,"=3")*3+COUNTIF(G21:G25,"3+VR")*3+COUNTIF(G21:G25,"3+VL")*3+COUNTIF(G21:G25,"VR+3")*3+COUNTIF(G21:G25,"VL+3")*3)+(COUNTIF(G30:G37,"=1")*1+COUNTIF(G30:G37,"1+VR")*1+COUNTIF(G30:G37,"1+VL")*1+COUNTIF(G30:G37,"1+VR+VL")*1+COUNTIF(G30:G37,"VR+1")*1+COUNTIF(G30:G37,"VL+1")*1+COUNTIF(G30:G37,"=2")*2+COUNTIF(G30:G37,"2+VR")*2+COUNTIF(G30:G37,"2+VL")*2+COUNTIF(G30:G37,"VR+2")*2+COUNTIF(G30:G37,"VL+2")*2+COUNTIF(G30:G37,"=3")*3+COUNTIF(G30:G37,"3+VR")*3+COUNTIF(G30:G37,"3+VL")*3+COUNTIF(G30:G37,"VR+3")*3+COUNTIF(G30:G37,"VL+3")*3)+(COUNTIF(G42:G50,"=1")*1+COUNTIF(G42:G50,"1+VR")*1+COUNTIF(G42:G50,"1+VL")*1+COUNTIF(G42:G50,"1+VR+VL")*1+COUNTIF(G42:G50,"VR+1")*1+COUNTIF(G42:G50,"VL+1")*1+COUNTIF(G42:G50,"=2")*2+COUNTIF(G42:G50,"2+VR")*2+COUNTIF(G42:G50,"2+VL")*2+COUNTIF(G42:G50,"VR+2")*2+COUNTIF(G42:G50,"VL+2")*2+COUNTIF(G42:G50,"=3")*3+COUNTIF(G42:G50,"3+VR")*3+COUNTIF(G42:G50,"3+VL")*3+COUNTIF(G42:G50,"VR+3")*3+COUNTIF(G42:G50,"VL+3")*3)+(COUNTIF(G55:G63,"=1")*1+COUNTIF(G55:G63,"1+VR")*1+COUNTIF(G55:G63,"1+VL")*1+COUNTIF(G55:G63,"1+VR+VL")*1+COUNTIF(G55:G63,"VR+1")*1+COUNTIF(G55:G63,"VL+1")*1+COUNTIF(G55:G63,"=2")*2+COUNTIF(G55:G63,"2+VR")*2+COUNTIF(G55:G63,"2+VL")*2+COUNTIF(G55:G63,"VR+2")*2+COUNTIF(G55:G63,"VL+2")*2+COUNTIF(G55:G63,"=3")*3+COUNTIF(G55:G63,"3+VR")*3+COUNTIF(G55:G63,"3+VL")*3+COUNTIF(G55:G63,"VR+3")*3+COUNTIF(G55:G63,"VL+3")*3)+(COUNTIF(G68:G75,"=1")*1+COUNTIF(G68:G75,"1+VR")*1+COUNTIF(G68:G75,"1+VL")*1+COUNTIF(G68:G75,"1+VR+VL")*1+COUNTIF(G68:G75,"VR+1")*1+COUNTIF(G68:G75,"VL+1")*1+COUNTIF(G68:G75,"=2")*2+COUNTIF(G68:G75,"2+VR")*2+COUNTIF(G68:G75,"2+VL")*2+COUNTIF(G68:G75,"VR+2")*2+COUNTIF(G68:G75,"VL+2")*2+COUNTIF(G68:G75,"=3")*3+COUNTIF(G68:G75,"3+VR")*3+COUNTIF(G68:G75,"3+VL")*3+COUNTIF(G68:G75,"VR+3")*3+COUNTIF(G68:G75,"VL+3")*3)+(COUNTIF(G80:G83,"=1")*1+COUNTIF(G80:G83,"1+VR")*1+COUNTIF(G80:G83,"1+VL")*1+COUNTIF(G80:G83,"1+VR+VL")*1+COUNTIF(G80:G83,"VR+1")*1+COUNTIF(G80:G83,"VL+1")*1+COUNTIF(G80:G83,"=2")*2+COUNTIF(G80:G83,"2+VR")*2+COUNTIF(G80:G83,"2+VL")*2+COUNTIF(G80:G83,"VR+2")*2+COUNTIF(G80:G83,"VL+2")*2+COUNTIF(G80:G83,"=3")*3+COUNTIF(G80:G83,"3+VR")*3+COUNTIF(G80:G83,"3+VL")*3+COUNTIF(G80:G83,"VR+3")*3+COUNTIF(G80:G83,"VL+3")*3)+(COUNTIF(G88:G91,"=1")*1+COUNTIF(G88:G91,"1+VR")*1+COUNTIF(G88:G91,"1+VL")*1+COUNTIF(G88:G91,"1+VR+VL")*1+COUNTIF(G88:G91,"VR+1")*1+COUNTIF(G88:G91,"VL+1")*1+COUNTIF(G88:G91,"=2")*2+COUNTIF(G88:G91,"2+VR")*2+COUNTIF(G88:G91,"2+VL")*2+COUNTIF(G88:G91,"VR+2")*2+COUNTIF(G88:G91,"VL+2")*2+COUNTIF(G88:G91,"=3")*3+COUNTIF(G88:G91,"3+VR")*3+COUNTIF(G88:G91,"3+VL")*3+COUNTIF(G88:G91,"VR+3")*3+COUNTIF(G88:G91,"VL+3")*3)+(COUNTIF(G96:G105,"=1")*1+COUNTIF(G96:G105,"1+VR")*1+COUNTIF(G96:G105,"1+VL")*1+COUNTIF(G96:G105,"1+VR+VL")*1+COUNTIF(G96:G105,"VR+1")*1+COUNTIF(G96:G105,"VL+1")*1+COUNTIF(G96:G105,"=2")*2+COUNTIF(G96:G105,"2+VR")*2+COUNTIF(G96:G105,"2+VL")*2+COUNTIF(G96:G105,"VR+2")*2+COUNTIF(G96:G105,"VL+2")*2+COUNTIF(G96:G105,"=3")*3+COUNTIF(G96:G105,"3+VR")*3+COUNTIF(G96:G105,"3+VL")*3+COUNTIF(G96:G105,"VR+3")*3+COUNTIF(G96:G105,"VL+3")*3)+(COUNTIF(G110:G115,"=1")*1+COUNTIF(G110:G115,"1+VR")*1+COUNTIF(G110:G115,"1+VL")*1+COUNTIF(G110:G115,"1+VR+VL")*1+COUNTIF(G110:G115,"VR+1")*1+COUNTIF(G110:G115,"VL+1")*1+COUNTIF(G110:G115,"=2")*2+COUNTIF(G110:G115,"2+VR")*2+COUNTIF(G110:G115,"2+VL")*2+COUNTIF(G110:G115,"VR+2")*2+COUNTIF(G110:G115,"VL+2")*2+COUNTIF(G110:G115,"=3")*3+COUNTIF(G110:G115,"3+VR")*3+COUNTIF(G110:G115,"3+VL")*3+COUNTIF(G110:G115,"VR+3")*3+COUNTIF(G110:G115,"VL+3")*3)+(COUNTIF(G120:G125,"=1")*1+COUNTIF(G120:G125,"1+VR")*1+COUNTIF(G120:G125,"1+VL")*1+COUNTIF(G120:G125,"1+VR+VL")*1+COUNTIF(G120:G125,"VR+1")*1+COUNTIF(G120:G125,"VL+1")*1+COUNTIF(G120:G125,"=2")*2+COUNTIF(G120:G125,"2+VR")*2+COUNTIF(G120:G125,"2+VL")*2+COUNTIF(G120:G125,"VR+2")*2+COUNTIF(G120:G125,"VL+2")*2+COUNTIF(G120:G125,"=3")*3+COUNTIF(G120:G125,"3+VR")*3+COUNTIF(G120:G125,"3+VL")*3+COUNTIF(G120:G125,"VR+3")*3+COUNTIF(G120:G125,"VL+3")*3)+(COUNTIF(G130:G131,"=1")*1+COUNTIF(G130:G131,"1+VR")*1+COUNTIF(G130:G131,"1+VL")*1+COUNTIF(G130:G131,"1+VR+VL")*1+COUNTIF(G130:G131,"VR+1")*1+COUNTIF(G130:G131,"VL+1")*1+COUNTIF(G130:G131,"=2")*2+COUNTIF(G130:G131,"2+VR")*2+COUNTIF(G130:G131,"2+VL")*2+COUNTIF(G130:G131,"VR+2")*2+COUNTIF(G130:G131,"VL+2")*2+COUNTIF(G130:G131,"=3")*3+COUNTIF(G130:G131,"3+VR")*3+COUNTIF(G130:G131,"3+VL")*3+COUNTIF(G130:G131,"VR+3")*3+COUNTIF(G130:G131,"VL+3")*3)+(COUNTIF(G136:G137,"=1")*1+COUNTIF(G136:G137,"1+VR")*1+COUNTIF(G136:G137,"1+VL")*1+COUNTIF(G136:G137,"1+VR+VL")*1+COUNTIF(G136:G137,"VR+1")*1+COUNTIF(G136:G137,"VL+1")*1+COUNTIF(G136:G137,"=2")*2+COUNTIF(G136:G137,"2+VR")*2+COUNTIF(G136:G137,"2+VL")*2+COUNTIF(G136:G137,"VR+2")*2+COUNTIF(G136:G137,"VL+2")*2+COUNTIF(G136:G137,"=3")*3+COUNTIF(G136:G137,"3+VR")*3+COUNTIF(G136:G137,"3+VL")*3+COUNTIF(G136:G137,"VR+3")*3+COUNTIF(G136:G137,"VL+3")*3)+(COUNTIF(G142:G147,"=1")*1+COUNTIF(G142:G147,"1+VR")*1+COUNTIF(G142:G147,"1+VL")*1+COUNTIF(G142:G147,"1+VR+VL")*1+COUNTIF(G142:G147,"VR+1")*1+COUNTIF(G142:G147,"VL+1")*1+COUNTIF(G142:G147,"=2")*2+COUNTIF(G142:G147,"2+VR")*2+COUNTIF(G142:G147,"2+VL")*2+COUNTIF(G142:G147,"VR+2")*2+COUNTIF(G142:G147,"VL+2")*2+COUNTIF(G142:G147,"=3")*3+COUNTIF(G142:G147,"3+VR")*3+COUNTIF(G142:G147,"3+VL")*3+COUNTIF(G142:G147,"VR+3")*3+COUNTIF(G142:G147,"VL+3")*3)+(COUNTIF(G152:G156,"=1")*1+COUNTIF(G152:G156,"1+VR")*1+COUNTIF(G152:G156,"1+VL")*1+COUNTIF(G152:G156,"1+VR+VL")*1+COUNTIF(G152:G156,"VR+1")*1+COUNTIF(G152:G156,"VL+1")*1+COUNTIF(G152:G156,"=2")*2+COUNTIF(G152:G156,"2+VR")*2+COUNTIF(G152:G156,"2+VL")*2+COUNTIF(G152:G156,"VR+2")*2+COUNTIF(G152:G156,"VL+2")*2+COUNTIF(G152:G156,"=3")*3+COUNTIF(G152:G156,"3+VR")*3+COUNTIF(G152:G156,"3+VL")*3+COUNTIF(G152:G156,"VR+3")*3+COUNTIF(G152:G156,"VL+3")*3)+(COUNTIF(G161:G163,"=1")*1+COUNTIF(G161:G163,"1+VR")*1+COUNTIF(G161:G163,"1+VL")*1+COUNTIF(G161:G163,"1+VR+VL")*1+COUNTIF(G161:G163,"VR+1")*1+COUNTIF(G161:G163,"VL+1")*1+COUNTIF(G161:G163,"=2")*2+COUNTIF(G161:G163,"2+VR")*2+COUNTIF(G161:G163,"2+VL")*2+COUNTIF(G161:G163,"VR+2")*2+COUNTIF(G161:G163,"VL+2")*2+COUNTIF(G161:G163,"=3")*3+COUNTIF(G161:G163,"3+VR")*3+COUNTIF(G161:G163,"3+VL")*3+COUNTIF(G161:G163,"VR+3")*3+COUNTIF(G161:G163,"VL+3")*3)+(COUNTIF(G168:G168,"=1")*1+COUNTIF(G168:G168,"1+VR")*1+COUNTIF(G168:G168,"1+VL")*1+COUNTIF(G168:G168,"1+VR+VL")*1+COUNTIF(G168:G168,"VR+1")*1+COUNTIF(G168:G168,"VL+1")*1+COUNTIF(G168:G168,"=2")*2+COUNTIF(G168:G168,"2+VR")*2+COUNTIF(G168:G168,"2+VL")*2+COUNTIF(G168:G168,"VR+2")*2+COUNTIF(G168:G168,"VL+2")*2+COUNTIF(G168:G168,"=3")*3+COUNTIF(G168:G168,"3+VR")*3+COUNTIF(G168:G168,"3+VL")*3+COUNTIF(G168:G168,"VR+3")*3+COUNTIF(G168:G168,"VL+3")*3)+(COUNTIF(P8:P14,"=1")*1+COUNTIF(P8:P14,"1+VR")*1+COUNTIF(P8:P14,"1+VL")*1+COUNTIF(P8:P14,"1+VR+VL")*1+COUNTIF(P8:P14,"VR+1")*1+COUNTIF(P8:P14,"VL+1")*1+COUNTIF(P8:P14,"=2")*2+COUNTIF(P8:P14,"2+VR")*2+COUNTIF(P8:P14,"2+VL")*2+COUNTIF(P8:P14,"VR+2")*2+COUNTIF(P8:P14,"VL+2")*2+COUNTIF(P8:P14,"=3")*3+COUNTIF(P8:P14,"3+VR")*3+COUNTIF(P8:P14,"3+VL")*3+COUNTIF(P8:P14,"VR+3")*3+COUNTIF(P8:P14,"VL+3")*3)+(COUNTIF(P19:P25,"=1")*1+COUNTIF(P19:P25,"1+VR")*1+COUNTIF(P19:P25,"1+VL")*1+COUNTIF(P19:P25,"1+VR+VL")*1+COUNTIF(P19:P25,"VR+1")*1+COUNTIF(P19:P25,"VL+1")*1+COUNTIF(P19:P25,"=2")*2+COUNTIF(P19:P25,"2+VR")*2+COUNTIF(P19:P25,"2+VL")*2+COUNTIF(P19:P25,"VR+2")*2+COUNTIF(P19:P25,"VL+2")*2+COUNTIF(P19:P25,"=3")*3+COUNTIF(P19:P25,"3+VR")*3+COUNTIF(P19:P25,"3+VL")*3+COUNTIF(P19:P25,"VR+3")*3+COUNTIF(P19:P25,"VL+3")*3) | H3: =(COUNTIF(H8:H16,"=1")*1+COUNTIF(H8:H16,"1+VR")*1+COUNTIF(H8:H16,"1+VL")*1+COUNTIF(H8:H16,"1+VR+VL")*1+COUNTIF(H8:H16,"VR+1")*1+COUNTIF(H8:H16,"VL+1")*1+COUNTIF(H8:H16,"=2")*2+COUNTIF(H8:H16,"2+VR")*2+COUNTIF(H8:H16,"2+VL")*2+COUNTIF(H8:H16,"VR+2")*2+COUNTIF(H8:H16,"VL+2")*2+COUNTIF(H8:H16,"=3")*3+COUNTIF(H8:H16,"3+VR")*3+COUNTIF(H8:H16,"3+VL")*3+COUNTIF(H8:H16,"VR+3")*3+COUNTIF(H8:H16,"VL+3")*3)+(COUNTIF(H21:H25,"=1")*1+COUNTIF(H21:H25,"1+VR")*1+COUNTIF(H21:H25,"1+VL")*1+COUNTIF(H21:H25,"1+VR+VL")*1+COUNTIF(H21:H25,"VR+1")*1+COUNTIF(H21:H25,"VL+1")*1+COUNTIF(H21:H25,"=2")*2+COUNTIF(H21:H25,"2+VR")*2+COUNTIF(H21:H25,"2+VL")*2+COUNTIF(H21:H25,"VR+2")*2+COUNTIF(H21:H25,"VL+2")*2+COUNTIF(H21:H25,"=3")*3+COUNTIF(H21:H25,"3+VR")*3+COUNTIF(H21:H25,"3+VL")*3+COUNTIF(H21:H25,"VR+3")*3+COUNTIF(H21:H25,"VL+3")*3)+(COUNTIF(H30:H37,"=1")*1+COUNTIF(H30:H37,"1+VR")*1+COUNTIF(H30:H37,"1+VL")*1+COUNTIF(H30:H37,"1+VR+VL")*1+COUNTIF(H30:H37,"VR+1")*1+COUNTIF(H30:H37,"VL+1")*1+COUNTIF(H30:H37,"=2")*2+COUNTIF(H30:H37,"2+VR")*2+COUNTIF(H30:H37,"2+VL")*2+COUNTIF(H30:H37,"VR+2")*2+COUNTIF(H30:H37,"VL+2")*2+COUNTIF(H30:H37,"=3")*3+COUNTIF(H30:H37,"3+VR")*3+COUNTIF(H30:H37,"3+VL")*3+COUNTIF(H30:H37,"VR+3")*3+COUNTIF(H30:H37,"VL+3")*3)+(COUNTIF(H42:H50,"=1")*1+COUNTIF(H42:H50,"1+VR")*1+COUNTIF(H42:H50,"1+VL")*1+COUNTIF(H42:H50,"1+VR+VL")*1+COUNTIF(H42:H50,"VR+1")*1+COUNTIF(H42:H50,"VL+1")*1+COUNTIF(H42:H50,"=2")*2+COUNTIF(H42:H50,"2+VR")*2+COUNTIF(H42:H50,"2+VL")*2+COUNTIF(H42:H50,"VR+2")*2+COUNTIF(H42:H50,"VL+2")*2+COUNTIF(H42:H50,"=3")*3+COUNTIF(H42:H50,"3+VR")*3+COUNTIF(H42:H50,"3+VL")*3+COUNTIF(H42:H50,"VR+3")*3+COUNTIF(H42:H50,"VL+3")*3)+(COUNTIF(H55:H63,"=1")*1+COUNTIF(H55:H63,"1+VR")*1+COUNTIF(H55:H63,"1+VL")*1+COUNTIF(H55:H63,"1+VR+VL")*1+COUNTIF(H55:H63,"VR+1")*1+COUNTIF(H55:H63,"VL+1")*1+COUNTIF(H55:H63,"=2")*2+COUNTIF(H55:H63,"2+VR")*2+COUNTIF(H55:H63,"2+VL")*2+COUNTIF(H55:H63,"VR+2")*2+COUNTIF(H55:H63,"VL+2")*2+COUNTIF(H55:H63,"=3")*3+COUNTIF(H55:H63,"3+VR")*3+COUNTIF(H55:H63,"3+VL")*3+COUNTIF(H55:H63,"VR+3")*3+COUNTIF(H55:H63,"VL+3")*3)+(COUNTIF(H68:H75,"=1")*1+COUNTIF(H68:H75,"1+VR")*1+COUNTIF(H68:H75,"1+VL")*1+COUNTIF(H68:H75,"1+VR+VL")*1+COUNTIF(H68:H75,"VR+1")*1+COUNTIF(H68:H75,"VL+1")*1+COUNTIF(H68:H75,"=2")*2+COUNTIF(H68:H75,"2+VR")*2+COUNTIF(H68:H75,"2+VL")*2+COUNTIF(H68:H75,"VR+2")*2+COUNTIF(H68:H75,"VL+2")*2+COUNTIF(H68:H75,"=3")*3+COUNTIF(H68:H75,"3+VR")*3+COUNTIF(H68:H75,"3+VL")*3+COUNTIF(H68:H75,"VR+3")*3+COUNTIF(H68:H75,"VL+3")*3)+(COUNTIF(H80:H83,"=1")*1+COUNTIF(H80:H83,"1+VR")*1+COUNTIF(H80:H83,"1+VL")*1+COUNTIF(H80:H83,"1+VR+VL")*1+COUNTIF(H80:H83,"VR+1")*1+COUNTIF(H80:H83,"VL+1")*1+COUNTIF(H80:H83,"=2")*2+COUNTIF(H80:H83,"2+VR")*2+COUNTIF(H80:H83,"2+VL")*2+COUNTIF(H80:H83,"VR+2")*2+COUNTIF(H80:H83,"VL+2")*2+COUNTIF(H80:H83,"=3")*3+COUNTIF(H80:H83,"3+VR")*3+COUNTIF(H80:H83,"3+VL")*3+COUNTIF(H80:H83,"VR+3")*3+COUNTIF(H80:H83,"VL+3")*3)+(COUNTIF(H88:H91,"=1")*1+COUNTIF(H88:H91,"1+VR")*1+COUNTIF(H88:H91,"1+VL")*1+COUNTIF(H88:H91,"1+VR+VL")*1+COUNTIF(H88:H91,"VR+1")*1+COUNTIF(H88:H91,"VL+1")*1+COUNTIF(H88:H91,"=2")*2+COUNTIF(H88:H91,"2+VR")*2+COUNTIF(H88:H91,"2+VL")*2+COUNTIF(H88:H91,"VR+2")*2+COUNTIF(H88:H91,"VL+2")*2+COUNTIF(H88:H91,"=3")*3+COUNTIF(H88:H91,"3+VR")*3+COUNTIF(H88:H91,"3+VL")*3+COUNTIF(H88:H91,"VR+3")*3+COUNTIF(H88:H91,"VL+3")*3)+(COUNTIF(H96:H105,"=1")*1+COUNTIF(H96:H105,"1+VR")*1+COUNTIF(H96:H105,"1+VL")*1+COUNTIF(H96:H105,"1+VR+VL")*1+COUNTIF(H96:H105,"VR+1")*1+COUNTIF(H96:H105,"VL+1")*1+COUNTIF(H96:H105,"=2")*2+COUNTIF(H96:H105,"2+VR")*2+COUNTIF(H96:H105,"2+VL")*2+COUNTIF(H96:H105,"VR+2")*2+COUNTIF(H96:H105,"VL+2")*2+COUNTIF(H96:H105,"=3")*3+COUNTIF(H96:H105,"3+VR")*3+COUNTIF(H96:H105,"3+VL")*3+COUNTIF(H96:H105,"VR+3")*3+COUNTIF(H96:H105,"VL+3")*3)+(COUNTIF(H110:H115,"=1")*1+COUNTIF(H110:H115,"1+VR")*1+COUNTIF(H110:H115,"1+VL")*1+COUNTIF(H110:H115,"1+VR+VL")*1+COUNTIF(H110:H115,"VR+1")*1+COUNTIF(H110:H115,"VL+1")*1+COUNTIF(H110:H115,"=2")*2+COUNTIF(H110:H115,"2+VR")*2+COUNTIF(H110:H115,"2+VL")*2+COUNTIF(H110:H115,"VR+2")*2+COUNTIF(H110:H115,"VL+2")*2+COUNTIF(H110:H115,"=3")*3+COUNTIF(H110:H115,"3+VR")*3+COUNTIF(H110:H115,"3+VL")*3+COUNTIF(H110:H115,"VR+3")*3+COUNTIF(H110:H115,"VL+3")*3)+(COUNTIF(H120:H125,"=1")*1+COUNTIF(H120:H125,"1+VR")*1+COUNTIF(H120:H125,"1+VL")*1+COUNTIF(H120:H125,"1+VR+VL")*1+COUNTIF(H120:H125,"VR+1")*1+COUNTIF(H120:H125,"VL+1")*1+COUNTIF(H120:H125,"=2")*2+COUNTIF(H120:H125,"2+VR")*2+COUNTIF(H120:H125,"2+VL")*2+COUNTIF(H120:H125,"VR+2")*2+COUNTIF(H120:H125,"VL+2")*2+COUNTIF(H120:H125,"=3")*3+COUNTIF(H120:H125,"3+VR")*3+COUNTIF(H120:H125,"3+VL")*3+COUNTIF(H120:H125,"VR+3")*3+COUNTIF(H120:H125,"VL+3")*3)+(COUNTIF(H130:H131,"=1")*1+COUNTIF(H130:H131,"1+VR")*1+COUNTIF(H130:H131,"1+VL")*1+COUNTIF(H130:H131,"1+VR+VL")*1+COUNTIF(H130:H131,"VR+1")*1+COUNTIF(H130:H131,"VL+1")*1+COUNTIF(H130:H131,"=2")*2+COUNTIF(H130:H131,"2+VR")*2+COUNTIF(H130:H131,"2+VL")*2+COUNTIF(H130:H131,"VR+2")*2+COUNTIF(H130:H131,"VL+2")*2+COUNTIF(H130:H131,"=3")*3+COUNTIF(H130:H131,"3+VR")*3+COUNTIF(H130:H131,"3+VL")*3+COUNTIF(H130:H131,"VR+3")*3+COUNTIF(H130:H131,"VL+3")*3)+(COUNTIF(H136:H137,"=1")*1+COUNTIF(H136:H137,"1+VR")*1+COUNTIF(H136:H137,"1+VL")*1+COUNTIF(H136:H137,"1+VR+VL")*1+COUNTIF(H136:H137,"VR+1")*1+COUNTIF(H136:H137,"VL+1")*1+COUNTIF(H136:H137,"=2")*2+COUNTIF(H136:H137,"2+VR")*2+COUNTIF(H136:H137,"2+VL")*2+COUNTIF(H136:H137,"VR+2")*2+COUNTIF(H136:H137,"VL+2")*2+COUNTIF(H136:H137,"=3")*3+COUNTIF(H136:H137,"3+VR")*3+COUNTIF(H136:H137,"3+VL")*3+COUNTIF(H136:H137,"VR+3")*3+COUNTIF(H136:H137,"VL+3")*3)+(COUNTIF(H142:H147,"=1")*1+COUNTIF(H142:H147,"1+VR")*1+COUNTIF(H142:H147,"1+VL")*1+COUNTIF(H142:H147,"1+VR+VL")*1+COUNTIF(H142:H147,"VR+1")*1+COUNTIF(H142:H147,"VL+1")*1+COUNTIF(H142:H147,"=2")*2+COUNTIF(H142:H147,"2+VR")*2+COUNTIF(H142:H147,"2+VL")*2+COUNTIF(H142:H147,"VR+2")*2+COUNTIF(H142:H147,"VL+2")*2+COUNTIF(H142:H147,"=3")*3+COUNTIF(H142:H147,"3+VR")*3+COUNTIF(H142:H147,"3+VL")*3+COUNTIF(H142:H147,"VR+3")*3+COUNTIF(H142:H147,"VL+3")*3)+(COUNTIF(H152:H156,"=1")*1+COUNTIF(H152:H156,"1+VR")*1+COUNTIF(H152:H156,"1+VL")*1+COUNTIF(H152:H156,"1+VR+VL")*1+COUNTIF(H152:H156,"VR+1")*1+COUNTIF(H152:H156,"VL+1")*1+COUNTIF(H152:H156,"=2")*2+COUNTIF(H152:H156,"2+VR")*2+COUNTIF(H152:H156,"2+VL")*2+COUNTIF(H152:H156,"VR+2")*2+COUNTIF(H152:H156,"VL+2")*2+COUNTIF(H152:H156,"=3")*3+COUNTIF(H152:H156,"3+VR")*3+COUNTIF(H152:H156,"3+VL")*3+COUNTIF(H152:H156,"VR+3")*3+COUNTIF(H152:H156,"VL+3")*3)+(COUNTIF(H161:H163,"=1")*1+COUNTIF(H161:H163,"1+VR")*1+COUNTIF(H161:H163,"1+VL")*1+COUNTIF(H161:H163,"1+VR+VL")*1+COUNTIF(H161:H163,"VR+1")*1+COUNTIF(H161:H163,"VL+1")*1+COUNTIF(H161:H163,"=2")*2+COUNTIF(H161:H163,"2+VR")*2+COUNTIF(H161:H163,"2+VL")*2+COUNTIF(H161:H163,"VR+2")*2+COUNTIF(H161:H163,"VL+2")*2+COUNTIF(H161:H163,"=3")*3+COUNTIF(H161:H163,"3+VR")*3+COUNTIF(H161:H163,"3+VL")*3+COUNTIF(H161:H163,"VR+3")*3+COUNTIF(H161:H163,"VL+3")*3)+(COUNTIF(H168:H168,"=1")*1+COUNTIF(H168:H168,"1+VR")*1+COUNTIF(H168:H168,"1+VL")*1+COUNTIF(H168:H168,"1+VR+VL")*1+COUNTIF(H168:H168,"VR+1")*1+COUNTIF(H168:H168,"VL+1")*1+COUNTIF(H168:H168,"=2")*2+COUNTIF(H168:H168,"2+VR")*2+COUNTIF(H168:H168,"2+VL")*2+COUNTIF(H168:H168,"VR+2")*2+COUNTIF(H168:H168,"VL+2")*2+COUNTIF(H168:H168,"=3")*3+COUNTIF(H168:H168,"3+VR")*3+COUNTIF(H168:H168,"3+VL")*3+COUNTIF(H168:H168,"VR+3")*3+COUNTIF(H168:H168,"VL+3")*3)+(COUNTIF(Q8:Q14,"=1")*1+COUNTIF(Q8:Q14,"1+VR")*1+COUNTIF(Q8:Q14,"1+VL")*1+COUNTIF(Q8:Q14,"1+VR+VL")*1+COUNTIF(Q8:Q14,"VR+1")*1+COUNTIF(Q8:Q14,"VL+1")*1+COUNTIF(Q8:Q14,"=2")*2+COUNTIF(Q8:Q14,"2+VR")*2+COUNTIF(Q8:Q14,"2+VL")*2+COUNTIF(Q8:Q14,"VR+2")*2+COUNTIF(Q8:Q14,"VL+2")*2+COUNTIF(Q8:Q14,"=3")*3+COUNTIF(Q8:Q14,"3+VR")*3+COUNTIF(Q8:Q14,"3+VL")*3+COUNTIF(Q8:Q14,"VR+3")*3+COUNTIF(Q8:Q14,"VL+3")*3)+(COUNTIF(Q19:Q25,"=1")*1+COUNTIF(Q19:Q25,"1+VR")*1+COUNTIF(Q19:Q25,"1+VL")*1+COUNTIF(Q19:Q25,"1+VR+VL")*1+COUNTIF(Q19:Q25,"VR+1")*1+COUNTIF(Q19:Q25,"VL+1")*1+COUNTIF(Q19:Q25,"=2")*2+COUNTIF(Q19:Q25,"2+VR")*2+COUNTIF(Q19:Q25,"2+VL")*2+COUNTIF(Q19:Q25,"VR+2")*2+COUNTIF(Q19:Q25,"VL+2")*2+COUNTIF(Q19:Q25,"=3")*3+COUNTIF(Q19:Q25,"3+VR")*3+COUNTIF(Q19:Q25,"3+VL")*3+COUNTIF(Q19:Q25,"VR+3")*3+COUNTIF(Q19:Q25,"VL+3")*3)
